Workbook

Sheet aeo_fuel_price_factors
A1: region | B1: fuel_type | C1: data_source | D1: scenario | E1: units | F1: 2022 | G1: 2023 | H1: 2024 | I1: 2025 | J1: 2026 | K1: 2027 | L1: 2028 | M1: 2029 | N1: 2030 | O1: 2031 | P1: 2032 | Q1: 2033 | R1: 2034 | S1: 2035 | T1: 2036 | U1: 2037 | V1: 2038 | W1: 2039 | X1: 2040 | Y1: 2041 | Z1: 2042 | AA1: 2043 | AB1: 2044 | AC1: 2045 | AD1: 2046 | AE1: 2047 | AF1: 2048 | AG1: 2049 | AH1: 2050
A2: national | B2: propane | C2: AEO2023 | D2: AEO2022 Reference case | E2: 2022 $/MMBtu | F2: =aeo_fuel_price_projections!$F2/aeo_fuel_price_projections!$F2 -> 1 | G2: =aeo_fuel_price_projections!G2/aeo_fuel_price_projections!$F2 -> 0.99048472 | H2: =aeo_fuel_price_projections!H2/aeo_fuel_price_projections!$F2 -> 0.99239496 | I2: =aeo_fuel_price_projections!I2/aeo_fuel_price_projections!$F2 -> 0.98998159 | J2: =aeo_fuel_price_projections!J2/aeo_fuel_price_projections!$F2 -> 0.99366766 | K2: =aeo_fuel_price_projections!K2/aeo_fuel_price_projections!$F2 -> 1.0072006 | L2: =aeo_fuel_price_projections!L2/aeo_fuel_price_projections!$F2 -> 1.0296572 | M2: =aeo_fuel_price_projections!M2/aeo_fuel_price_projections!$F2 -> 1.0508905 | N2: =aeo_fuel_price_projections!N2/aeo_fuel_price_projections!$F2 -> 1.0728577 | ... AH2: =aeo_fuel_price_projections!AH2/aeo_fuel_price_projections!$F2 -> 1.2754047
A3: national | B3: propane | C3: AEO2023 | D3: AEO2023 Reference case | E3: 2022 $/MMBtu | F3: =aeo_fuel_price_projections!$F3/aeo_fuel_price_projections!$F3 -> 1 | G3: =aeo_fuel_price_projections!G3/aeo_fuel_price_projections!$F3 -> 1.0746016 | H3: =aeo_fuel_price_projections!H3/aeo_fuel_price_projections!$F3 -> 1.080856 | I3: =aeo_fuel_price_projections!I3/aeo_fuel_price_projections!$F3 -> 1.0439706 | J3: =aeo_fuel_price_projections!J3/aeo_fuel_price_projections!$F3 -> 1.0062926 | K3: =aeo_fuel_price_projections!K3/aeo_fuel_price_projections!$F3 -> 0.97593457 | L3: =aeo_fuel_price_projections!L3/aeo_fuel_price_projections!$F3 -> 0.95859768 | M3: =aeo_fuel_price_projections!M3/aeo_fuel_price_projections!$F3 -> 0.95206205 | N3: =aeo_fuel_price_projections!N3/aeo_fuel_price_projections!$F3 -> 0.95514031 | ... AH3: =aeo_fuel_price_projections!AH3/aeo_fuel_price_projections!$F3 -> 1.1314715
A4: national | B4: propane | C4: AEO2023 | D4: Low Zero-Carbon Technology Cost | E4: 2022 $/MMBtu | F4: =aeo_fuel_price_projections!$F4/aeo_fuel_price_projections!$F4 -> 1 | G4: =aeo_fuel_price_projections!G4/aeo_fuel_price_projections!$F4 -> 1.0746895 | H4: =aeo_fuel_price_projections!H4/aeo_fuel_price_projections!$F4 -> 1.084688 | I4: =aeo_fuel_price_projections!I4/aeo_fuel_price_projections!$F4 -> 1.0450646 | J4: =aeo_fuel_price_projections!J4/aeo_fuel_price_projections!$F4 -> 1.0048826 | K4: =aeo_fuel_price_projections!K4/aeo_fuel_price_projections!$F4 -> 0.97275118 | L4: =aeo_fuel_price_projections!L4/aeo_fuel_price_projections!$F4 -> 0.95282001 | M4: =aeo_fuel_price_projections!M4/aeo_fuel_price_projections!$F4 -> 0.94228086 | N4: =aeo_fuel_price_projections!N4/aeo_fuel_price_projections!$F4 -> 0.9410753 | ... AH4: =aeo_fuel_price_projections!AH4/aeo_fuel_price_projections!$F4 -> 1.1056612
A5: national | B5: propane | C5: AEO2023 | D5: No Inflation Reduction Act | E5: 2022 $/MMBtu | F5: =aeo_fuel_price_projections!$F5/aeo_fuel_price_projections!$F5 -> 1 | G5: =aeo_fuel_price_projections!G5/aeo_fuel_price_projections!$F5 -> 1.0697683 | H5: =aeo_fuel_price_projections!H5/aeo_fuel_price_projections!$F5 -> 1.0787244 | I5: =aeo_fuel_price_projections!I5/aeo_fuel_price_projections!$F5 -> 1.0421361 | J5: =aeo_fuel_price_projections!J5/aeo_fuel_price_projections!$F5 -> 1.0097997 | K5: =aeo_fuel_price_projections!K5/aeo_fuel_price_projections!$F5 -> 0.99172639 | L5: =aeo_fuel_price_projections!L5/aeo_fuel_price_projections!$F5 -> 0.98534049 | M5: =aeo_fuel_price_projections!M5/aeo_fuel_price_projections!$F5 -> 0.98695523 | N5: =aeo_fuel_price_projections!N5/aeo_fuel_price_projections!$F5 -> 0.99523975 | ... AH5: =aeo_fuel_price_projections!AH5/aeo_fuel_price_projections!$F5 -> 1.1518178
A6: national | B6: propane | C6: AEO2023 | D6: Low Uptake of Inflation Reduction Act | E6: 2022 $/MMBtu | F6: =aeo_fuel_price_projections!$F6/aeo_fuel_price_projections!$F6 -> 1 | G6: =aeo_fuel_price_projections!G6/aeo_fuel_price_projections!$F6 -> 1.0756025 | H6: =aeo_fuel_price_projections!H6/aeo_fuel_price_projections!$F6 -> 1.0853215 | I6: =aeo_fuel_price_projections!I6/aeo_fuel_price_projections!$F6 -> 1.0481687 | J6: =aeo_fuel_price_projections!J6/aeo_fuel_price_projections!$F6 -> 1.01404 | K6: =aeo_fuel_price_projections!K6/aeo_fuel_price_projections!$F6 -> 0.99259255 | L6: =aeo_fuel_price_projections!L6/aeo_fuel_price_projections!$F6 -> 0.98393193 | M6: =aeo_fuel_price_projections!M6/aeo_fuel_price_projections!$F6 -> 0.9835364 | N6: =aeo_fuel_price_projections!N6/aeo_fuel_price_projections!$F6 -> 0.99104669 | ... AH6: =aeo_fuel_price_projections!AH6/aeo_fuel_price_projections!$F6 -> 1.1382518
A7: national | B7: propane | C7: AEO2023 | D7: High Uptake of Inflation Reduction Act | E7: 2022 $/MMBtu | F7: =aeo_fuel_price_projections!$F7/aeo_fuel_price_projections!$F7 -> 1 | G7: =aeo_fuel_price_projections!G7/aeo_fuel_price_projections!$F7 -> 1.0754966 | H7: =aeo_fuel_price_projections!H7/aeo_fuel_price_projections!$F7 -> 1.0858692 | I7: =aeo_fuel_price_projections!I7/aeo_fuel_price_projections!$F7 -> 1.045761 | J7: =aeo_fuel_price_projections!J7/aeo_fuel_price_projections!$F7 -> 1.0046843 | K7: =aeo_fuel_price_projections!K7/aeo_fuel_price_projections!$F7 -> 0.97179427 | L7: =aeo_fuel_price_projections!L7/aeo_fuel_price_projections!$F7 -> 0.95101414 | M7: =aeo_fuel_price_projections!M7/aeo_fuel_price_projections!$F7 -> 0.94101427 | N7: =aeo_fuel_price_projections!N7/aeo_fuel_price_projections!$F7 -> 0.94195546 | ... AH7: =aeo_fuel_price_projections!AH7/aeo_fuel_price_projections!$F7 -> 1.1261338
A8: national | B8: fuelOil | C8: AEO2023 | D8: AEO2022 Reference case | E8: 2022 $/MMBtu | F8: =aeo_fuel_price_projections!$F8/aeo_fuel_price_projections!$F8 -> 1 | G8: =aeo_fuel_price_projections!G8/aeo_fuel_price_projections!$F8 -> 0.98539675 | H8: =aeo_fuel_price_projections!H8/aeo_fuel_price_projections!$F8 -> 1.0488632 | I8: =aeo_fuel_price_projections!I8/aeo_fuel_price_projections!$F8 -> 1.0728981 | J8: =aeo_fuel_price_projections!J8/aeo_fuel_price_projections!$F8 -> 1.0983925 | K8: =aeo_fuel_price_projections!K8/aeo_fuel_price_projections!$F8 -> 1.1275965 | L8: =aeo_fuel_price_projections!L8/aeo_fuel_price_projections!$F8 -> 1.1359469 | M8: =aeo_fuel_price_projections!M8/aeo_fuel_price_projections!$F8 -> 1.1414475 | N8: =aeo_fuel_price_projections!N8/aeo_fuel_price_projections!$F8 -> 1.1398054 | ... AH8: =aeo_fuel_price_projections!AH8/aeo_fuel_price_projections!$F8 -> 1.2376861
A9: national | B9: fuelOil | C9: AEO2023 | D9: AEO2023 Reference case | E9: 2022 $/MMBtu | F9: =aeo_fuel_price_projections!$F9/aeo_fuel_price_projections!$F9 -> 1 | G9: =aeo_fuel_price_projections!G9/aeo_fuel_price_projections!$F9 -> 0.93142356 | H9: =aeo_fuel_price_projections!H9/aeo_fuel_price_projections!$F9 -> 0.89703564 | I9: =aeo_fuel_price_projections!I9/aeo_fuel_price_projections!$F9 -> 0.85042495 | J9: =aeo_fuel_price_projections!J9/aeo_fuel_price_projections!$F9 -> 0.83724845 | K9: =aeo_fuel_price_projections!K9/aeo_fuel_price_projections!$F9 -> 0.82454151 | L9: =aeo_fuel_price_projections!L9/aeo_fuel_price_projections!$F9 -> 0.81650902 | M9: =aeo_fuel_price_projections!M9/aeo_fuel_price_projections!$F9 -> 0.81899829 | N9: =aeo_fuel_price_projections!N9/aeo_fuel_price_projections!$F9 -> 0.81922804 | ... AH9: =aeo_fuel_price_projections!AH9/aeo_fuel_price_projections!$F9 -> 0.86069588
A10: national | B10: fuelOil | C10: AEO2023 | D10: Low Zero-Carbon Technology Cost | E10: 2022 $/MMBtu | F10: =aeo_fuel_price_projections!$F10/aeo_fuel_price_projections!$F10 -> 1 | G10: =aeo_fuel_price_projections!G10/aeo_fuel_price_projections!$F10 -> 0.93142356 | H10: =aeo_fuel_price_projections!H10/aeo_fuel_price_projections!$F10 -> 0.90112502 | I10: =aeo_fuel_price_projections!I10/aeo_fuel_price_projections!$F10 -> 0.84633634 | J10: =aeo_fuel_price_projections!J10/aeo_fuel_price_projections!$F10 -> 0.82913792 | K10: =aeo_fuel_price_projections!K10/aeo_fuel_price_projections!$F10 -> 0.81711647 | L10: =aeo_fuel_price_projections!L10/aeo_fuel_price_projections!$F10 -> 0.81051969 | M10: =aeo_fuel_price_projections!M10/aeo_fuel_price_projections!$F10 -> 0.8125763 | N10: =aeo_fuel_price_projections!N10/aeo_fuel_price_projections!$F10 -> 0.81069451 | ... AH10: =aeo_fuel_price_projections!AH10/aeo_fuel_price_projections!$F10 -> 0.85420295
A11: national | B11: fuelOil | C11: AEO2023 | D11: No Inflation Reduction Act | E11: 2022 $/MMBtu | F11: =aeo_fuel_price_projections!$F11/aeo_fuel_price_projections!$F11 -> 1 | G11: =aeo_fuel_price_projections!G11/aeo_fuel_price_projections!$F11 -> 0.93142356 | H11: =aeo_fuel_price_projections!H11/aeo_fuel_price_projections!$F11 -> 0.90010103 | I11: =aeo_fuel_price_projections!I11/aeo_fuel_price_projections!$F11 -> 0.84729856 | J11: =aeo_fuel_price_projections!J11/aeo_fuel_price_projections!$F11 -> 0.83081133 | K11: =aeo_fuel_price_projections!K11/aeo_fuel_price_projections!$F11 -> 0.81991613 | L11: =aeo_fuel_price_projections!L11/aeo_fuel_price_projections!$F11 -> 0.80684072 | M11: =aeo_fuel_price_projections!M11/aeo_fuel_price_projections!$F11 -> 0.80982099 | N11: =aeo_fuel_price_projections!N11/aeo_fuel_price_projections!$F11 -> 0.81076042 | ... AH11: =aeo_fuel_price_projections!AH11/aeo_fuel_price_projections!$F11 -> 0.85355183
A12: national | B12: fuelOil | C12: AEO2023 | D12: Low Uptake of Inflation Reduction Act | E12: 2022 $/MMBtu | F12: =aeo_fuel_price_projections!$F12/aeo_fuel_price_projections!$F12 -> 1 | G12: =aeo_fuel_price_projections!G12/aeo_fuel_price_projections!$F12 -> 0.93142356 | H12: =aeo_fuel_price_projections!H12/aeo_fuel_price_projections!$F12 -> 0.90015614 | I12: =aeo_fuel_price_projections!I12/aeo_fuel_price_projections!$F12 -> 0.84617517 | J12: =aeo_fuel_price_projections!J12/aeo_fuel_price_projections!$F12 -> 0.8301212 | K12: =aeo_fuel_price_projections!K12/aeo_fuel_price_projections!$F12 -> 0.81873631 | L12: =aeo_fuel_price_projections!L12/aeo_fuel_price_projections!$F12 -> 0.81096591 | M12: =aeo_fuel_price_projections!M12/aeo_fuel_price_projections!$F12 -> 0.81338734 | N12: =aeo_fuel_price_projections!N12/aeo_fuel_price_projections!$F12 -> 0.81136356 | ... AH12: =aeo_fuel_price_projections!AH12/aeo_fuel_price_projections!$F12 -> 0.85262301
A13: national | B13: fuelOil | C13: AEO2023 | D13: High Uptake of Inflation Reduction Act | E13: 2022 $/MMBtu | F13: =aeo_fuel_price_projections!$F13/aeo_fuel_price_projections!$F13 -> 1 | G13: =aeo_fuel_price_projections!G13/aeo_fuel_price_projections!$F13 -> 0.93142356 | H13: =aeo_fuel_price_projections!H13/aeo_fuel_price_projections!$F13 -> 0.90127757 | I13: =aeo_fuel_price_projections!I13/aeo_fuel_price_projections!$F13 -> 0.84645194 | J13: =aeo_fuel_price_projections!J13/aeo_fuel_price_projections!$F13 -> 0.83028481 | K13: =aeo_fuel_price_projections!K13/aeo_fuel_price_projections!$F13 -> 0.81778166 | L13: =aeo_fuel_price_projections!L13/aeo_fuel_price_projections!$F13 -> 0.80984221 | M13: =aeo_fuel_price_projections!M13/aeo_fuel_price_projections!$F13 -> 0.81180048 | N13: =aeo_fuel_price_projections!N13/aeo_fuel_price_projections!$F13 -> 0.81151931 | ... AH13: =aeo_fuel_price_projections!AH13/aeo_fuel_price_projections!$F13 -> 0.85418229
... A241: Pacific | B241: electricity | C241: AEO2023 | D241: AEO2022 Reference case | E241: 2022 $/MMBtu | F241: =aeo_fuel_price_projections!$F241/aeo_fuel_price_projections!$F241 -> 1 | G241: =aeo_fuel_price_projections!G241/aeo_fuel_price_projections!$F241 -> 0.95568387 | H241: =aeo_fuel_price_projections!H241/aeo_fuel_price_projections!$F241 -> 0.89749927 | I241: =aeo_fuel_price_projections!I241/aeo_fuel_price_projections!$F241 -> 0.90586835 | J241: =aeo_fuel_price_projections!J241/aeo_fuel_price_projections!$F241 -> 0.93408696 | K241: =aeo_fuel_price_projections!K241/aeo_fuel_price_projections!$F241 -> 0.94362382 | L241: =aeo_fuel_price_projections!L241/aeo_fuel_price_projections!$F241 -> 0.9538015 | M241: =aeo_fuel_price_projections!M241/aeo_fuel_price_projections!$F241 -> 0.95920009 | N241: =aeo_fuel_price_projections!N241/aeo_fuel_price_projections!$F241 -> 0.9687309 | ... AH241: =aeo_fuel_price_projections!AH241/aeo_fuel_price_projections!$F241 -> 1.0777446

Sheet aeo_fuel_price_projections
A1: region | B1: fuel_type | C1: data_source | D1: scenario | E1: units | F1: 2022 | G1: 2023 | H1: 2024 | I1: 2025 | J1: 2026 | K1: 2027 | L1: 2028 | M1: 2029 | N1: 2030 | O1: 2031 | P1: 2032 | Q1: 2033 | R1: 2034 | S1: 2035 | T1: 2036 | U1: 2037 | V1: 2038 | W1: 2039 | X1: 2040 | Y1: 2041 | Z1: 2042 | AA1: 2043 | AB1: 2044 | AC1: 2045 | AD1: 2046 | AE1: 2047 | AF1: 2048 | AG1: 2049 | AH1: 2050
A2: national | B2: propane | C2: AEO2023 | D2: AEO2022 Reference case | E2: 2022 $/MMBtu | F2: 23.220642 | G2: 22.999691 | H2: 23.044048 | I2: 22.988008 | J2: 23.073601 | K2: 23.387844 | L2: 23.909302 | M2: 24.402353 | N2: 24.912445 | O2: 25.580082 | P2: 26.018036 | Q2: 26.452085 | R2: 26.77109 | S2: 27.01306 | T2: 27.24498 | U2: 27.496624 | V2: 27.743568 | W2: 27.926832 | X2: 28.22287 | Y2: 28.480589 | Z2: 28.620867 | AA2: 28.824804 | AB2: 29.072638 | AC2: 29.213709 | AD2: 29.365524 | AE2: 29.49081 | AF2: 29.580093 | AG2: 29.612167 | AH2: 29.615717
A3: national | B3: propane | C3: AEO2023 | D3: AEO2023 Reference case | E3: 2022 $/MMBtu | F3: 29.133368 | G3: 31.306763 | H3: 31.488976 | I3: 30.414381 | J3: 29.316694 | K3: 28.432261 | L3: 27.927179 | M3: 27.736774 | N3: 27.826454 | O3: 28.114607 | P3: 28.577341 | Q3: 29.166182 | R3: 29.755032 | S3: 30.227194 | T3: 30.581852 | U3: 30.898972 | V3: 31.307201 | W3: 31.50728 | X3: 31.831757 | Y3: 32.150085 | Z3: 32.377548 | AA3: 32.495739 | AB3: 32.527752 | AC3: 32.601685 | AD3: 32.818344 | AE3: 32.85873 | AF3: 32.944168 | AG3: 32.974564 | AH3: 32.963577
A4: national | B4: propane | C4: AEO2023 | D4: Low Zero-Carbon Technology Cost | E4: 2022 $/MMBtu | F4: 29.133368 | G4: 31.309324 | H4: 31.600616 | I4: 30.446253 | J4: 29.275616 | K4: 28.339518 | L4: 27.758856 | M4: 27.451815 | N4: 27.416693 | O4: 27.603905 | P4: 27.976286 | Q4: 28.541294 | R4: 29.207626 | S4: 29.791668 | T4: 30.211325 | U4: 30.527035 | V4: 30.856184 | W4: 31.111874 | X4: 31.456388 | Y4: 31.767973 | Z4: 31.983889 | AA4: 32.090343 | AB4: 32.159275 | AC4: 32.23447 | AD4: 32.255539 | AE4: 32.462818 | AF4: 32.428272 | AG4: 32.308121 | AH4: 32.211636
A5: national | B5: propane | C5: AEO2023 | D5: No Inflation Reduction Act | E5: 2022 $/MMBtu | F5: 29.133368 | G5: 31.165955 | H5: 31.426876 | I5: 30.360935 | J5: 29.418867 | K5: 28.89233 | L5: 28.706287 | M5: 28.75333 | N5: 28.994686 | O5: 29.294603 | P5: 29.694832 | Q5: 30.142426 | R5: 30.480944 | S5: 30.798513 | T5: 31.114361 | U5: 31.488482 | V5: 31.936584 | W5: 32.372803 | X5: 32.569668 | Y5: 32.654289 | Z5: 32.70295 | AA5: 32.695557 | AB5: 32.751099 | AC5: 32.850124 | AD5: 33.022053 | AE5: 33.203354 | AF5: 33.330925 | AG5: 33.406353 | AH5: 33.556332
A6: national | B6: propane | C6: AEO2023 | D6: Low Uptake of Inflation Reduction Act | E6: 2022 $/MMBtu | F6: 29.133368 | G6: 31.335922 | H6: 31.61907 | I6: 30.536684 | J6: 29.5424 | K6: 28.917564 | L6: 28.665251 | M6: 28.653728 | N6: 28.872528 | O6: 29.146534 | P6: 29.541458 | Q6: 30.014538 | R6: 30.449997 | S6: 30.779417 | T6: 31.09445 | U6: 31.467447 | V6: 31.834185 | W6: 32.207844 | X6: 32.616589 | Y6: 32.820332 | Z6: 32.956291 | AA6: 33.016518 | AB6: 32.974667 | AC6: 32.930065 | AD6: 32.939915 | AE6: 33.040508 | AF6: 33.115822 | AG6: 33.112083 | AH6: 33.16111
A7: national | B7: propane | C7: AEO2023 | D7: High Uptake of Inflation Reduction Act | E7: 2022 $/MMBtu | F7: 29.133368 | G7: 31.332838 | H7: 31.635027 | I7: 30.466539 | J7: 29.269838 | K7: 28.31164 | L7: 27.706245 | M7: 27.414915 | N7: 27.442335 | O7: 27.672113 | P7: 28.11841 | Q7: 28.680885 | R7: 29.297104 | S7: 29.839947 | T7: 30.233749 | U7: 30.561764 | V7: 30.937773 | W7: 31.200384 | X7: 31.579121 | Y7: 31.957531 | Z7: 32.231171 | AA7: 32.324947 | AB7: 32.399109 | AC7: 32.425827 | AD7: 32.499702 | AE7: 32.561184 | AF7: 32.84193 | AG7: 32.836082 | AH7: 32.808071
A8: national | B8: fuelOil | C8: AEO2023 | D8: AEO2022 Reference case | E8: 2022 $/MMBtu | F8: 22.032839 | G8: 21.711088 | H8: 23.109434 | I8: 23.63899 | J8: 24.200705 | K8: 24.844152 | L8: 25.028135 | M8: 25.149328 | N8: 25.113148 | O8: 25.38743 | P8: 25.491673 | Q8: 25.554348 | R8: 25.603569 | S8: 25.682781 | T8: 25.852264 | U8: 26.068512 | V8: 26.195641 | W8: 26.263983 | X8: 26.487915 | Y8: 26.585123 | Z8: 26.597675 | AA8: 26.824036 | AB8: 27.082211 | AC8: 27.180676 | AD8: 27.386578 | AE8: 27.415541 | AF8: 27.337561 | AG8: 27.322523 | AH8: 27.269739
A9: national | B9: fuelOil | C9: AEO2023 | D9: AEO2023 Reference case | E9: 2022 $/MMBtu | F9: 35.242496 | G9: 32.825691 | H9: 31.613775 | I9: 29.971098 | J9: 29.506725 | K9: 29.058901 | L9: 28.775816 | M9: 28.863544 | N9: 28.871641 | O9: 29.047983 | P9: 29.134987 | Q9: 29.251019 | R9: 29.296843 | S9: 29.470129 | T9: 29.486605 | U9: 29.608255 | V9: 29.697092 | W9: 29.738928 | X9: 29.786015 | Y9: 29.942484 | Z9: 29.935656 | AA9: 30.04907 | AB9: 29.954853 | AC9: 29.998642 | AD9: 30.208778 | AE9: 30.235264 | AF9: 30.267241 | AG9: 30.332973 | AH9: 30.333071
A10: national | B10: fuelOil | C10: AEO2023 | D10: Low Zero-Carbon Technology Cost | E10: 2022 $/MMBtu | F10: 35.242496 | G10: 32.825691 | H10: 31.757895 | I10: 29.827005 | J10: 29.22089 | K10: 28.797224 | L10: 28.564737 | M10: 28.637217 | N10: 28.570898 | O10: 28.735826 | P10: 28.825449 | Q10: 28.943003 | R10: 29.039227 | S10: 29.154503 | T10: 29.2444 | U10: 29.37648 | V10: 29.507236 | W10: 29.53072 | X10: 29.642384 | Y10: 29.801661 | Z10: 29.842705 | AA10: 29.867744 | AB10: 29.845247 | AC10: 29.909998 | AD10: 29.984671 | AE10: 30.163315 | AF10: 30.129372 | AG10: 30.130142 | AH10: 30.104244
A11: national | B11: fuelOil | C11: AEO2023 | D11: No Inflation Reduction Act | E11: 2022 $/MMBtu | F11: 35.242496 | G11: 32.825691 | H11: 31.721807 | I11: 29.860916 | J11: 29.279865 | K11: 28.895891 | L11: 28.435081 | M11: 28.540113 | N11: 28.573221 | O11: 28.666229 | P11: 28.786097 | Q11: 28.946541 | R11: 28.957058 | S11: 29.048769 | T11: 29.197708 | U11: 29.276814 | V11: 29.356138 | W11: 29.502115 | X11: 29.522913 | Y11: 29.586622 | Z11: 29.621849 | AA11: 29.669392 | AB11: 29.708973 | AC11: 29.790016 | AD11: 29.937336 | AE11: 30.007732 | AF11: 30.023258 | AG11: 30.047739 | AH11: 30.081297
A12: national | B12: fuelOil | C12: AEO2023 | D12: Low Uptake of Inflation Reduction Act | E12: 2022 $/MMBtu | F12: 35.242496 | G12: 32.825691 | H12: 31.723749 | I12: 29.821325 | J12: 29.255543 | K12: 28.854311 | L12: 28.580463 | M12: 28.6658 | N12: 28.594477 | O12: 28.786793 | P12: 28.904512 | Q12: 29.010462 | R12: 29.080723 | S12: 29.116213 | T12: 29.257763 | U12: 29.36458 | V12: 29.451283 | W12: 29.505381 | X12: 29.581089 | Y12: 29.646725 | Z12: 29.684948 | AA12: 29.722742 | AB12: 29.806511 | AC12: 29.889389 | AD12: 29.979275 | AE12: 30.02569 | AF12: 30.00913 | AG12: 30.005342 | AH12: 30.048563
... A241: Pacific | B241: electricity | C241: AEO2023 | D241: AEO2022 Reference case | E241: 2022 $/MMBtu | F241: 51.06105 | G241: 48.798222 | H241: 45.827255 | I241: 46.254589 | J241: 47.695461 | K241: 48.182423 | L241: 48.702106 | M241: 48.977764 | N241: 49.464417 | O241: 50.426376 | P241: 51.129818 | Q241: 51.494186 | R241: 51.903599 | S241: 52.034691 | T241: 52.087936 | U241: 52.170639 | V241: 52.287926 | W241: 52.353111 | X241: 52.456795 | Y241: 52.630028 | Z241: 52.901608 | AA241: 53.1847 | AB241: 53.434864 | AC241: 53.714279 | AD241: 54.080086 | AE241: 54.357922 | AF241: 54.575043 | AG241: 54.844898 | AH241: 55.030769

Sheet aeo_hdd_factors

Sheet aeo_hdd_factors (2)

Sheet aeo2019_2023_change_comparison
A1: Key Indicators | E1: AEO 2019 | F1: AEO2023
A2: Households (millions) | B2: full name | C2: api key | D2: units | E2: 2018 | F2: 2022 | G2: % Change
A3: Single-Family | B3: Residential: Key Indicators: Households: Single-Family: Reference case | C3: AEO.2019.REF2019.KEI_HHD_RESD_SFR_NA_NA_USA_MILL.A | D3: millions | E3: 82.704849 | F3: 86.924255 | G3: =((F3-E3)/F3)*100 -> 4.8541181
A4: Multifamily | B4: Residential: Key Indicators: Households: Multifamily: Reference case | C4: AEO.2019.REF2019.KEI_HHD_RESD_MFR_NA_NA_USA_MILL.A | D4: millions | E4: 31.247095 | F4: 32.842152 | G4: =((F4-E4)/F4)*100 -> 4.8567372
A5: Mobile Homes | B5: Residential: Key Indicators: Households: Mobile Homes: Reference case | C5: AEO.2019.REF2019.KEI_HHD_RESD_MBH_NA_NA_USA_MILL.A | D5: millions | E5: 6.397799 | F5: 6.648376 | G5: =((F5-E5)/F5)*100 -> 3.7689956
A6: Total | B6: Residential: Key Indicators: Households: Total: Reference case | C6: AEO.2019.REF2019.KEI_HHD_RESD_TEN_NA_NA_USA_MILL.A | D6: millions | E6: 120.34974 | F6: 126.41478 | G6: =((F6-E6)/F6)*100 -> 4.7977309
A8: Average House Square Footage | B8: Residential: Key Indicators: Average House Square Footage: Reference case | C8: AEO.2019.REF2019.KEI_HHD_RESD_NA_NA_NA_USA_SQFT.A | D8: sq ft | E8: 1778.8584 | F8: 1798.9158 | G8: =((F8-E8)/F8)*100 -> 1.1149701
A10: Energy Intensity
A11: Delivered Energy Consumption | B11: Residential: Household Energy Intensity: Delivered Energy Use: Reference case | C11: AEO.2019.REF2019.INY_HHD_RESD_DELE_NA_NA_USA_MILLBTUPHOSD.A | D11: MMBtu/household | E11: 94.872032 | F11: 93.023323 | G11: =((F11-E11)/F11)*100 -> -1.9873607
A12: Delivered Energy Consumption | B12: Residential: Energy Intensity per Square Foot: Delivered Energy Use: Reference case | C12: AEO.2019.REF2019.INY_HHD_RESD_DELE_NA_NA_USA_THBTUPSQFT.A | D12: thousand Btu/sq ft | E12: 53.333099 | F12: 51.710773 | G12: =((F12-E12)/F12)*100 -> -3.1373076
A14: Delivered Energy Consumption by Fuel
A15: Purchased Electricity
A16: Space Heating | B16: Residential: Electricity: Space Heating: Reference case | C16: AEO.2019.REF2019.CNSM_HHD_RESD_SPH_ELC_NA_USA_QBTU.A | D16: quads | E16: 0.707306 | F16: 0.74562 | G16: =((F16-E16)/F16)*100 -> 5.1385424
A17: Water Heating | B17: Residential: Electricity: Water Heating: Reference case | C17: AEO.2019.REF2019.CNSM_NA_RESD_WTHT_ELC_NA_USA_QBTU.A | D17: quads | E17: 0.592269 | F17: 0.599797 | G17: =((F17-E17)/F17)*100 -> 1.2550913
A18: Cooking | B18: Residential: Electricity: Cooking: Reference case | C18: AEO.2019.REF2019.CNSM_NA_RESD_CGR_ELC_NA_USA_QBTU.A | D18: quads | E18: 0.053819 | F18: 0.055863 | G18: =((F18-E18)/F18)*100 -> 3.6589514
A19: Clothes Dryers | B19: Residential: Electricity: Clothes Dryers: Reference case | C19: AEO.2019.REF2019.CNSM_NA_RESD_CDR_ELC_NA_USA_QBTU.A | D19: quads | E19: 0.205106 | F19: 0.222467 | G19: =((F19-E19)/F19)*100 -> 7.8038541
A20: Delivered Energy | B20: Residential: Electricity: Delivered Energy: Reference case | C20: AEO.2019.REF2019.CNSM_NA_RESD_DELE_ELC_NA_USA_QBTU.A | D20: quads | E20: 4.987749 | F20: 5.147618 | G20: =((F20-E20)/F20)*100 -> 3.1056889
A22: Natural Gas
A23: Space Heating | B23: Residential: Natural Gas: Space Heating: Reference case | C23: AEO.2019.REF2019.CNSM_NA_RESD_SPH_NG_NA_USA_QBTU.A | D23: quads | E23: 3.585862 | F23: 3.73693 | G23: =((F23-E23)/F23)*100 -> 4.0425697
A24: Water Heating | B24: Residential: Natural Gas: Water Heating: Reference case | C24: AEO.2019.REF2019.CNSM_NA_RESD_WTHT_NG_NA_USA_QBTU.A | D24: quads | E24: 0.996691 | F24: 0.982988 | G24: =((F24-E24)/F24)*100 -> -1.394015
A25: Cooking | B25: Residential: Natural Gas: Cooking: Reference case | C25: AEO.2019.REF2019.CNSM_NA_RESD_CGR_NG_NA_USA_QBTU.A | D25: quads | E25: 0.102506 | F25: 0.103539 | G25: =((F25-E25)/F25)*100 -> 0.99769169
A26: Clothes Dryers | B26: Residential: Natural Gas: Clothes Dryers: Reference case | C26: AEO.2019.REF2019.CNSM_NA_RESD_CDR_NG_NA_USA_QBTU.A | D26: quads | E26: 0.037757 | F26: 0.039713 | G26: =((F26-E26)/F26)*100 -> 4.9253393
A27: Delivered Energy | B27: Residential: Natural Gas: Delivered Energy: Reference case | C27: AEO.2019.REF2019.CNSM_NA_RESD_DELE_NG_NA_USA_QBTU.A | D27: quads | E27: 5.015778 | F27: 5.149392 | G27: =((F27-E27)/F27)*100 -> 2.5947529
A29: Distillate Fuel Oil
A30: Space Heating | B30: Residential: Distillate Fuel Oil: Space Heating: Reference case | C30: AEO.2019.REF2019.CNSM_NA_RESD_SPH_DFO_NA_USA_QBTU.A | D30: quads | E30: 0.415463 | F30: 0.381925 | G30: =((F30-E30)/F30)*100 -> -8.7813052
A31: Water Heating | B31: Residential: Distillate Fuel Oil: Water Heating: Reference case | C31: AEO.2019.REF2019.CNSM_NA_RESD_WTHT_DFO_NA_USA_QBTU.A | D31: quads | E31: 0.052595 | F31: 0.043041 | G31: =((F31-E31)/F31)*100 -> -22.19744
A32: Delivered Energy | B32: Residential: Distillate Fuel Oil: Delivered Energy: Reference case | C32: AEO.2019.REF2019.CNSM_NA_RESD_NA_DFO_NA_USA_QBTU.A | D32: quads | E32: 0.488138 | F32: 0.432497 | G32: =((F32-E32)/F32)*100 -> -12.86506
A34: Propane
A35: Space Heating | B35: Residential: Propane: Space Heating: Reference case | C35: AEO.2019.REF2019.CNSM_NA_RESD_SPH_PROP_NA_USA_QBTU.A | D35: quads | E35: 0.348067 | F35: 0.340393 | G35: =((F35-E35)/F35)*100 -> -2.2544529
A36: Water Heating | B36: Residential: Propane: Water Heating: Reference case | C36: AEO.2019.REF2019.CNSM_NA_RESD_WTHT_PROP_NA_USA_QBTU.A | D36: quads | E36: 0.067313 | F36: 0.060221 | G36: =((F36-E36)/F36)*100 -> -11.776623
A37: Cooking | B37: Residential: Propane: Cooking: Reference case | C37: AEO.2019.REF2019.CNSM_NA_RESD_CGR_PROP_NA_USA_QBTU.A | D37: quads | E37: 0.016921 | F37: 0.016931 | G37: =((F37-E37)/F37)*100 -> 0.059063257
A38: Delivered Energy | B38: Residential: Propane: Delivered Energy: Reference case | C38: AEO.2019.REF2019.CNSM_NA_RESD_DELE_PROP_NA_USA_QBTU.A | D38: quads | E38: 0.499132 | F38: 0.491085 | G38: =((F38-E38)/F38)*100 -> -1.6386165
A40: Delivered Energy Consumption by End Use
A41: Space Heating | B41: Residential: Delivered Energy Use by End Use: Space Heating: Reference case | C41: AEO.2019.REF2019.CNSM_NA_RESD_SPH_DEE_NA_USA_QBTU.A | D41: quads | E41: 5.49605 | F41: 5.743799 | G41: =((F41-E41)/F41)*100 -> 4.3133299
A42: Water Heating | B42: Residential: Delivered Energy Use by End Use: Water Heating: Reference case | C42: AEO.2019.REF2019.CNSM_NA_RESD_WTHT_DEE_NA_USA_QBTU.A | D42: quads | E42: 1.708869 | F42: 1.686047 | G42: =((F42-E42)/F42)*100 -> -1.3535803
A43: Cooking | B43: Residential: Delivered Energy Use by End Use: Cooking: Reference case | C43: AEO.2019.REF2019.CNSM_NA_RESD_CGR_DEE_NA_USA_QBTU.A | D43: quads | E43: 0.173246 | F43: 0.176332 | G43: =((F43-E43)/F43)*100 -> 1.7501078
A44: Clothes Dryers | B44: Residential: Delivered Energy Use by End Use: Clothes Dryers: Reference case | C44: AEO.2019.REF2019.CNSM_NA_RESD_CDR_DEE_NA_USA_QBTU.A | D44: quads | E44: 0.242863 | F44: 0.262179 | G44: =((F44-E44)/F44)*100 -> 7.3674856
A45: Delivered Energy | B45: Residential: Delivered Energy Use by End Use: Delivered Energy: Reference case | C45: AEO.2019.REF2019.CNSM_NA_RESD_NA_DEE_NA_USA_QBTU.A | D45: quads | E45: 11.417824 | F45: 11.759521 | G45: =((F45-E45)/F45)*100 -> 2.9057051

Sheet aeo2019_key_indicators
A1: Residential Sector Key Indicators and Consumption
A2: https://www.eia.gov/outlooks/aeo/data/browser/#/?id=4-AEO2019&region=0-0&cases=ref2019&start=2017&end=2018&f=A&linechart=ref2019-d111618a.4-4-AEO2019&sourcekey=0
A3: Sat Aug 10 2024 22:58:47 GMT-0400 (Eastern Daylight Time)
A4: Source: U.S. Energy Information Administration
B5: full name | C5: api key | D5: units | E5: 2017 | F5: 2018 | G5: Growth (2018-2050)
A6: Key Indicators
A7: Households (millions)
A8: Single-Family | B8: Residential: Key Indicators: Households: Single-Family: Reference case | C8: AEO.2019.REF2019.KEI_HHD_RESD_SFR_NA_NA_USA_MILL.A | D8: millions | E8: 82.02993 | F8: 82.704849 | G8: 0.008
A9: Multifamily | B9: Residential: Key Indicators: Households: Multifamily: Reference case | C9: AEO.2019.REF2019.KEI_HHD_RESD_MFR_NA_NA_USA_MILL.A | D9: millions | E9: 30.983019 | F9: 31.247095 | G9: 0.007
A10: Mobile Homes | B10: Residential: Key Indicators: Households: Mobile Homes: Reference case | C10: AEO.2019.REF2019.KEI_HHD_RESD_MBH_NA_NA_USA_MILL.A | D10: millions | E10: 6.505692 | F10: 6.397799 | G10: -0.008
A11: Total | B11: Residential: Key Indicators: Households: Total: Reference case | C11: AEO.2019.REF2019.KEI_HHD_RESD_TEN_NA_NA_USA_MILL.A | D11: millions | E11: 119.51864 | F11: 120.34974 | G11: 0.007
A12: Average House Square Footage | B12: Residential: Key Indicators: Average House Square Footage: Reference case | C12: AEO.2019.REF2019.KEI_HHD_RESD_NA_NA_NA_USA_SQFT.A | D12: sq ft | E12: 1771.9004 | F12: 1778.8584 | G12: 0.003
A13: Energy Intensity
A14: (million Btu per household)
A15: Delivered Energy Consumption | B15: Residential: Household Energy Intensity: Delivered Energy Use: Reference case | C15: AEO.2019.REF2019.INY_HHD_RESD_DELE_NA_NA_USA_MILLBTUPHOSD.A | D15: MMBtu/household | E15: 88.689323 | F15: 94.872032 | G15: -0.008
A16: Total Energy Consumption | B16: Residential: Household Energy Intensity: Total Energy Use: Reference case | C16: AEO.2019.REF2019.INY_HHD_RESD_TEN_NA_NA_USA_MILLBTUPHOSD.A | D16: MMBtu/household | E16: 166.28271 | F16: 175.53064 | G16: -0.009
A17: (thousand Btu per square foot)
A18: Delivered Energy Consumption | B18: Residential: Energy Intensity per Square Foot: Delivered Energy Use: Reference case | C18: AEO.2019.REF2019.INY_HHD_RESD_DELE_NA_NA_USA_THBTUPSQFT.A | D18: thousand Btu/sq ft | E18: 50.053219 | F18: 53.333099 | G18: -0.011
A19: Total Energy Consumption | B19: Residential: Energy Intensity per Square Foot: Total Energy Use: Reference case | C19: AEO.2019.REF2019.INY_HHD_RESD_TEN_NA_NA_USA_THBTUPSQFT.A | D19: thousand Btu/sq ft | E19: 93.844276 | F19: 98.676003 | G19: -0.012
A20: Delivered Energy Consumption by Fuel
A21: Purchased Electricity
A22: Space Heating | B22: Residential: Electricity: Space Heating: Reference case | C22: AEO.2019.REF2019.CNSM_HHD_RESD_SPH_ELC_NA_USA_QBTU.A | D22: quads | E22: 0.540594 | F22: 0.707306 | G22: -0.013
A23: Space Cooling | B23: Residential: Electricity: Space Cooling: Reference case | C23: AEO.2019.REF2019.CNSM_NA_RESD_SPC_ELC_NA_USA_QBTU.A | D23: quads | E23: 0.605617 | F23: 0.730971 | G23: 0.008
A24: Water Heating | B24: Residential: Electricity: Water Heating: Reference case | C24: AEO.2019.REF2019.CNSM_NA_RESD_WTHT_ELC_NA_USA_QBTU.A | D24: quads | E24: 0.587852 | F24: 0.592269 | G24: 0
A25: Refrigeration | B25: Residential: Electricity: Refrigeration: Reference case | C25: AEO.2019.REF2019.CNSM_NA_RESD_REFR_ELC_NA_USA_QBTU.A | D25: quads | E25: 0.298958 | F25: 0.297264 | G25: 0.003
A26: Cooking | B26: Residential: Electricity: Cooking: Reference case | C26: AEO.2019.REF2019.CNSM_NA_RESD_CGR_ELC_NA_USA_QBTU.A | D26: quads | E26: 0.053618 | F26: 0.053819 | G26: 0.003
A27: Clothes Dryers | B27: Residential: Electricity: Clothes Dryers: Reference case | C27: AEO.2019.REF2019.CNSM_NA_RESD_CDR_ELC_NA_USA_QBTU.A | D27: quads | E27: 0.200623 | F27: 0.205106 | G27: 0.011
A28: Freezers | B28: Residential: Electricity: Freezers: Reference case | C28: AEO.2019.REF2019.CNSM_NA_RESD_FRZ_ELC_NA_USA_QBTU.A | D28: quads | E28: 0.069091 | F28: 0.068774 | G28: -0.001
A29: Lighting | B29: Residential: Electricity: Lighting: Reference case | C29: AEO.2019.REF2019.CNSM_NA_RESD_LGHTNG_ELC_NA_USA_QBTU.A | D29: quads | E29: 0.32583 | F29: 0.31159 | G29: -0.015
A30: Clothes Washers | B30: Residential: Electricity: Clothes Washers: Reference case | C30: AEO.2019.REF2019.CNSM_NA_RESD_CLW_ELC_NA_USA_QBTU.A | D30: quads | E30: 0.035439 | F30: 0.035714 | G30: 0.008
A31: Dishwashers | B31: Residential: Electricity: Dishwashers: Reference case | C31: AEO.2019.REF2019.CNSM_NA_RESD_DSW_ELC_NA_USA_QBTU.A | D31: quads | E31: 0.025043 | F31: 0.02547 | G31: 0.016
A32: Televisions and Related Equipment | B32: Residential: Electricity: Televisions: Reference case | C32: AEO.2019.REF2019.CNSM_NA_RESD_TVR_ELC_NA_USA_QBTU.A | D32: quads | E32: 0.216622 | F32: 0.212622 | G32: 0.007
A33: Computers and Related Equipment | B33: Residential: Electricity: Computers: Reference case | C33: AEO.2019.REF2019.CNSM_NA_RESD_CMPR_ELC_NA_USA_QBTU.A | D33: quads | E33: 0.093065 | F33: 0.090292 | G33: -0.027
... A36: Delivered Energy | B36: Residential: Electricity: Delivered Energy: Reference case | C36: AEO.2019.REF2019.CNSM_NA_RESD_DELE_ELC_NA_USA_QBTU.A | D36: quads | E36: 4.704531 | F36: 4.987749 | G36: 0.004
A37: Natural Gas
A38: Space Heating | B38: Residential: Natural Gas: Space Heating: Reference case | C38: AEO.2019.REF2019.CNSM_NA_RESD_SPH_NG_NA_USA_QBTU.A | D38: quads | E38: 3.15162 | F38: 3.585862 | G38: -0.006
A39: Space Cooling | B39: Residential: Natural Gas: Space Cooling: Reference case | C39: AEO.2019.REF2019.CNSM_NA_RESD_SPC_NG_NA_USA_QBTU.A | D39: quads | E39: 0.055534 | F39: 0.062704 | G39: -0.006
A40: Water Heating | B40: Residential: Natural Gas: Water Heating: Reference case | C40: AEO.2019.REF2019.CNSM_NA_RESD_WTHT_NG_NA_USA_QBTU.A | D40: quads | E40: 0.997965 | F40: 0.996691 | G40: 0.006
A41: Cooking | B41: Residential: Natural Gas: Cooking: Reference case | C41: AEO.2019.REF2019.CNSM_NA_RESD_CGR_NG_NA_USA_QBTU.A | D41: quads | E41: 0.102527 | F41: 0.102506 | G41: 0.005
A42: Clothes Dryers | B42: Residential: Natural Gas: Clothes Dryers: Reference case | C42: AEO.2019.REF2019.CNSM_NA_RESD_CDR_NG_NA_USA_QBTU.A | D42: quads | E42: 0.037273 | F42: 0.037757 | G42: 0.012
...

Sheet aeo2023_key_indicators
A1: Table 4. Residential Sector Key Indicators and Consumption
A2: https://www.eia.gov/outlooks/aeo/data/browser/#/?id=4-AEO2023&region=0-0&cases=ref2023&start=2021&end=2022&f=A&sourcekey=0
A3: Sat Aug 10 2024 22:55:45 GMT-0400 (Eastern Daylight Time)
A4: Source: U.S. Energy Information Administration
B5: full name | C5: api key | D5: units | E5: 2021 | F5: 2022 | G5: Growth (2022-2050)
A6: Key Indicators
A7: Households (millions)
A8: Single-Family | B8: Residential: Key Indicators: Households: Single-Family: Reference case | C8: AEO.2023.REF2023.KEI_HHD_RESD_SFR_NA_NA_USA_MILL.A | D8: millions | F8: 86.924255 | G8: 0.008
A9: Multifamily | B9: Residential: Key Indicators: Households: Multifamily: Reference case | C9: AEO.2023.REF2023.KEI_HHD_RESD_MFR_NA_NA_USA_MILL.A | D9: millions | F9: 32.842152 | G9: 0.008
A10: Mobile Homes | B10: Residential: Key Indicators: Households: Mobile Homes: Reference case | C10: AEO.2023.REF2023.KEI_HHD_RESD_MBH_NA_NA_USA_MILL.A | D10: millions | F10: 6.648376 | G10: 0.001
A11: Total | B11: Residential: Key Indicators: Households: Total: Reference case | C11: AEO.2023.REF2023.KEI_HHD_RESD_TEN_NA_NA_USA_MILL.A | D11: millions | F11: 126.41478 | G11: 0.008
A12: Average House Square Footage | B12: Residential: Key Indicators: Average House Square Footage: Reference case | C12: AEO.2023.REF2023.KEI_HHD_RESD_NA_NA_NA_USA_SQFT.A | D12: sq ft | F12: 1798.9158 | G12: 0.002
A13: Energy Intensity
A14: (million Btu per household)
A15: Gross End-use Consumption | B15: Residential: Household Energy Intensity: Gross End-use Consumption: Reference case | C15: AEO.2023.REF2023.INY_HHD_RESD_DELE_NA_NA_USA_MILLBTUPHOSD.A | D15: MMBtu/household | F15: 93.909477 | G15: -0.006
A16: Delivered Energy Consumption | B16: Residential: Household Energy Intensity: Delivered Energy Consumption: Reference case | C16: AEO.2023.REF2023.INY_HHD_RESD_TEN_NA_NA_USA_MILLBTUPHOSD.A | D16: MMBtu/household | F16: 93.023323 | G16: -0.007
A17: (thousand Btu per square foot)
A18: Gross End-use Consumption | B18: Residential: Energy Intensity per Square Foot: Gross End-use Consumption: Reference case | C18: AEO.2023.REF2023.INY_HHD_RESD_DELE_NA_NA_USA_THBTUPSQFT.A | D18: thousand Btu/sq ft | F18: 52.203377 | G18: -0.008
A19: Delivered Energy Consumption | B19: Residential: Energy Intensity per Square Foot: Delivered Energy Consumption: Reference case | C19: AEO.2023.REF2023.INY_HHD_RESD_TEN_NA_NA_USA_THBTUPSQFT.A | D19: thousand Btu/sq ft | F19: 51.710773 | G19: -0.009
A20: Energy Consumption by Fuel
A21: Electricity
A22: Space Heating | B22: Residential: Electricity: Space Heating: Reference case | C22: AEO.2023.REF2023.CNSM_HHD_RESD_SPH_ELC_NA_USA_QBTU.A | D22: quads | F22: 0.74562 | G22: -0.013
A23: Space Cooling | B23: Residential: Electricity: Space Cooling: Reference case | C23: AEO.2023.REF2023.CNSM_NA_RESD_SPC_ELC_NA_USA_QBTU.A | D23: quads | F23: 0.853587 | G23: 0.019
A24: Water Heating | B24: Residential: Electricity: Water Heating: Reference case | C24: AEO.2023.REF2023.CNSM_NA_RESD_WTHT_ELC_NA_USA_QBTU.A | D24: quads | F24: 0.599797 | G24: 0.002
A25: Refrigeration | B25: Residential: Electricity: Refrigeration: Reference case | C25: AEO.2023.REF2023.CNSM_NA_RESD_REFR_ELC_NA_USA_QBTU.A | D25: quads | F25: 0.295558 | G25: 0.005
A26: Cooking | B26: Residential: Electricity: Cooking: Reference case | C26: AEO.2023.REF2023.CNSM_NA_RESD_CGR_ELC_NA_USA_QBTU.A | D26: quads | F26: 0.055863 | G26: 0.004
A27: Clothes Dryers | B27: Residential: Electricity: Clothes Dryers: Reference case | C27: AEO.2023.REF2023.CNSM_NA_RESD_CDR_ELC_NA_USA_QBTU.A | D27: quads | F27: 0.222467 | G27: 0.014
A28: Freezers | B28: Residential: Electricity: Freezers: Reference case | C28: AEO.2023.REF2023.CNSM_NA_RESD_FRZ_ELC_NA_USA_QBTU.A | D28: quads | F28: 0.069007 | G28: 0.001
A29: Lighting | B29: Residential: Electricity: Lighting: Reference case | C29: AEO.2023.REF2023.CNSM_NA_RESD_LGHTNG_ELC_NA_USA_QBTU.A | D29: quads | F29: 0.22927 | G29: -0.005
A30: Clothes Washers | B30: Residential: Electricity: Clothes Washers: Reference case | C30: AEO.2023.REF2023.CNSM_NA_RESD_CLW_ELC_NA_USA_QBTU.A | D30: quads | F30: 0.037489 | G30: 0.008
A31: Dishwashers | B31: Residential: Electricity: Dishwashers: Reference case | C31: AEO.2023.REF2023.CNSM_NA_RESD_DSW_ELC_NA_USA_QBTU.A | D31: quads | F31: 0.027618 | G31: 0.017
A32: Televisions and Related Equipment | B32: Residential: Electricity: Televisions: Reference case | C32: AEO.2023.REF2023.CNSM_NA_RESD_TVR_ELC_NA_USA_QBTU.A | D32: quads | F32: 0.185092 | G32: -0.01
A33: Computers and Related Equipment | B33: Residential: Electricity: Computers: Reference case | C33: AEO.2023.REF2023.CNSM_NA_RESD_CMPR_ELC_NA_USA_QBTU.A | D33: quads | F33: 0.120106 | G33: -0.022
... A38: Purchased Electricity | B38: Residential: Electricity: Purchased Electricity: Reference case | C38: AEO.2023.REF2023.CNSM_NA_RESD_DELE_ELC_NA_USA_QBTU.A | D38: quads | F38: 5.147618 | G38: 0.007
A39: Natural Gas
A40: Space Heating | B40: Residential: Natural Gas: Space Heating: Reference case | C40: AEO.2023.REF2023.CNSM_NA_RESD_SPH_NG_NA_USA_QBTU.A | D40: quads | F40: 3.73693 | G40: -0.006
A41: Space Cooling | B41: Residential: Natural Gas: Space Cooling: Reference case | C41: AEO.2023.REF2023.CNSM_NA_RESD_SPC_NG_NA_USA_QBTU.A | D41: quads | F41: 0.058888 | G41: 0.002
A42: Water Heating | B42: Residential: Natural Gas: Water Heating: Reference case | C42: AEO.2023.REF2023.CNSM_NA_RESD_WTHT_NG_NA_USA_QBTU.A | D42: quads | F42: 0.982988 | G42: 0.008
A43: Cooking | B43: Residential: Natural Gas: Cooking: Reference case | C43: AEO.2023.REF2023.CNSM_NA_RESD_CGR_NG_NA_USA_QBTU.A | D43: quads | F43: 0.103539 | G43: 0.006
A44: Clothes Dryers | B44: Residential: Natural Gas: Clothes Dryers: Reference case | C44: AEO.2023.REF2023.CNSM_NA_RESD_CDR_NG_NA_USA_QBTU.A | D44: quads | F44: 0.039713 | G44: 0.015
...
