Workbook

Sheet proc_Cambium22_coal_gea
A1: data_source | B1: scenario | C1: gea_region | D1: year | E1: coal_MWh
A2: Cambium_2022 | B2: MidCase | C2: =Cambium22_MidCase_annual_gea!A7 -> AZNMc | D2: =Cambium22_MidCase_annual_gea!B7 -> 2024 | E2: =Cambium22_MidCase_annual_gea!CA7 -> 22849070
A3: Cambium_2022 | B3: MidCase | C3: =Cambium22_MidCase_annual_gea!A8 -> AZNMc | D3: =Cambium22_MidCase_annual_gea!B8 -> 2026 | E3: =Cambium22_MidCase_annual_gea!CA8 -> 21009922
A4: Cambium_2022 | B4: MidCase | C4: =Cambium22_MidCase_annual_gea!A9 -> AZNMc | D4: =Cambium22_MidCase_annual_gea!B9 -> 2028 | E4: =Cambium22_MidCase_annual_gea!CA9 -> 14483350
A5: Cambium_2022 | B5: MidCase | C5: =Cambium22_MidCase_annual_gea!A10 -> AZNMc | D5: =Cambium22_MidCase_annual_gea!B10 -> 2030 | E5: =Cambium22_MidCase_annual_gea!CA10 -> 13433882
A6: Cambium_2022 | B6: MidCase | C6: =Cambium22_MidCase_annual_gea!A11 -> AZNMc | D6: =Cambium22_MidCase_annual_gea!B11 -> 2035 | E6: =Cambium22_MidCase_annual_gea!CA11 -> 8231337.5
A7: Cambium_2022 | B7: MidCase | C7: =Cambium22_MidCase_annual_gea!A12 -> AZNMc | D7: =Cambium22_MidCase_annual_gea!B12 -> 2040 | E7: =Cambium22_MidCase_annual_gea!CA12 -> 6037824
A8: Cambium_2022 | B8: MidCase | C8: =Cambium22_MidCase_annual_gea!A13 -> AZNMc | D8: =Cambium22_MidCase_annual_gea!B13 -> 2045 | E8: =Cambium22_MidCase_annual_gea!CA13 -> 5122842.5
A9: Cambium_2022 | B9: MidCase | C9: =Cambium22_MidCase_annual_gea!A14 -> AZNMc | D9: =Cambium22_MidCase_annual_gea!B14 -> 2050 | E9: =Cambium22_MidCase_annual_gea!CA14 -> 5555184
A10: Cambium_2022 | B10: MidCase | C10: =Cambium22_MidCase_annual_gea!A15 -> CAMXc | D10: =Cambium22_MidCase_annual_gea!B15 -> 2024 | E10: =Cambium22_MidCase_annual_gea!CA15 -> 0
A11: Cambium_2022 | B11: MidCase | C11: =Cambium22_MidCase_annual_gea!A16 -> CAMXc | D11: =Cambium22_MidCase_annual_gea!B16 -> 2026 | E11: =Cambium22_MidCase_annual_gea!CA16 -> 0
A12: Cambium_2022 | B12: MidCase | C12: =Cambium22_MidCase_annual_gea!A17 -> CAMXc | D12: =Cambium22_MidCase_annual_gea!B17 -> 2028 | E12: =Cambium22_MidCase_annual_gea!CA17 -> 0
A13: Cambium_2022 | B13: MidCase | C13: =Cambium22_MidCase_annual_gea!A18 -> CAMXc | D13: =Cambium22_MidCase_annual_gea!B18 -> 2030 | E13: =Cambium22_MidCase_annual_gea!CA18 -> 0
... A161: Cambium_2022 | B161: MidCase | C161: =Cambium22_MidCase_annual_gea!A166 -> SRVCc | D161: =Cambium22_MidCase_annual_gea!B166 -> 2050 | E161: =Cambium22_MidCase_annual_gea!CA166 -> 1924772.2

Sheet proc_Cambium22_Delta_gea
A1: data_source | B1: scenario | C1: gea_region | D1: year | E1: cef_gen | F1: aer_gen_co2e | G1: lrmer_co2e | H1: srmer_co2e | I1: total_generation | J1: canada_generation | K1: biomass | L1: total_generation_adjusted | M1: total_coal | N1: total_natural_gas | O1: total_oil | P1: total_nuclear | Q1: total_renewable | R1: fraction_coal | S1: fraction_natural_gas | T1: fraction_oil | U1: fraction_nuclear | V1: fraction_renewable
A2: Cambium_2022 | B2: MidCase | C2: AZNMc | D2: 2024 | E2: 0.63 | F2: 279.4 | G2: 326.9 | H2: 777.1 | I2: =proc_Cambium22_highElec_gea!AE2-proc_Cambium22_MidCase_gea!AE2 -> 2421200 | J2: =proc_Cambium22_highElec_gea!AF2-proc_Cambium22_MidCase_gea!AF2 -> 0 | K2: =proc_Cambium22_highElec_gea!AG2-proc_Cambium22_MidCase_gea!AG2 -> -1203.5 | L2: =proc_Cambium22_highElec_gea!AH2-proc_Cambium22_MidCase_gea!AH2 -> 2422403.5 | M2: =proc_Cambium22_highElec_gea!AI2-proc_Cambium22_MidCase_gea!AI2 -> -75468 | N2: =proc_Cambium22_highElec_gea!AJ2-proc_Cambium22_MidCase_gea!AJ2 -> -78808 | O2: =proc_Cambium22_highElec_gea!AK2-proc_Cambium22_MidCase_gea!AK2 -> 3399.2 | P2: =proc_Cambium22_highElec_gea!AL2-proc_Cambium22_MidCase_gea!AL2 -> -144256 | Q2: =proc_Cambium22_highElec_gea!AM2-proc_Cambium22_MidCase_gea!AM2 -> 2717523.9 | R2: =M2/L2 -> -0.031154182 | S2: =N2/L2 -> -0.032532978 | T2: =O2/L2 -> 0.0014032344 | U2: =P2/L2 -> -0.059550773 | V2: =Q2/L2 -> 1.1218296
A3: Cambium_2022 | B3: MidCase | C3: AZNMc | D3: 2026 | E3: 0.69 | F3: 237.5 | G3: 193.9 | H3: 709.7 | I3: =proc_Cambium22_highElec_gea!AE3-proc_Cambium22_MidCase_gea!AE3 -> 2295920 | J3: =proc_Cambium22_highElec_gea!AF3-proc_Cambium22_MidCase_gea!AF3 -> 0 | K3: =proc_Cambium22_highElec_gea!AG3-proc_Cambium22_MidCase_gea!AG3 -> -249 | L3: =I3-J3-K3 -> 2296169 | M3: =proc_Cambium22_highElec_gea!AI3-proc_Cambium22_MidCase_gea!AI3 -> 734604 | N3: =proc_Cambium22_highElec_gea!AJ3-proc_Cambium22_MidCase_gea!AJ3 -> -327586.7 | O3: =proc_Cambium22_highElec_gea!AK3-proc_Cambium22_MidCase_gea!AK3 -> -4338.3 | P3: =proc_Cambium22_highElec_gea!AL3-proc_Cambium22_MidCase_gea!AL3 -> -36112 | Q3: =proc_Cambium22_highElec_gea!AM3-proc_Cambium22_MidCase_gea!AM3 -> 1929606.6 | R3: =M3/L3 -> 0.31992593 | S3: =N3/L3 -> -0.14266663 | T3: =O3/L3 -> -0.0018893644 | U3: =P3/L3 -> -0.015727065 | V3: =Q3/L3 -> 0.84035914
A4: Cambium_2022 | B4: MidCase | C4: AZNMc | D4: 2028 | E4: 0.8 | F4: 157.9 | G4: 130.5 | H4: 576.4 | I4: =proc_Cambium22_highElec_gea!AE4-proc_Cambium22_MidCase_gea!AE4 -> 4084500 | J4: =proc_Cambium22_highElec_gea!AF4-proc_Cambium22_MidCase_gea!AF4 -> 0 | K4: =proc_Cambium22_highElec_gea!AG4-proc_Cambium22_MidCase_gea!AG4 -> 2068.7 | L4: =I4-J4-K4 -> 4082431.3 | M4: =proc_Cambium22_highElec_gea!AI4-proc_Cambium22_MidCase_gea!AI4 -> 2297552 | N4: =proc_Cambium22_highElec_gea!AJ4-proc_Cambium22_MidCase_gea!AJ4 -> 1137310 | O4: =proc_Cambium22_highElec_gea!AK4-proc_Cambium22_MidCase_gea!AK4 -> -2269.4 | P4: =proc_Cambium22_highElec_gea!AL4-proc_Cambium22_MidCase_gea!AL4 -> 125168 | Q4: =proc_Cambium22_highElec_gea!AM4-proc_Cambium22_MidCase_gea!AM4 -> 524675.9 | R4: =M4/L4 -> 0.56279012 | S4: =N4/L4 -> 0.27858644 | T4: =O4/L4 -> -0.00055589423 | U4: =P4/L4 -> 0.030660161 | V4: =Q4/L4 -> 0.12852045
A5: Cambium_2022 | B5: MidCase | C5: AZNMc | D5: 2030 | E5: 0.84 | F5: 133.3 | G5: 103.7 | H5: 486.7 | I5: =proc_Cambium22_highElec_gea!AE5-proc_Cambium22_MidCase_gea!AE5 -> 19053960 | J5: =proc_Cambium22_highElec_gea!AF5-proc_Cambium22_MidCase_gea!AF5 -> 0 | K5: =proc_Cambium22_highElec_gea!AG5-proc_Cambium22_MidCase_gea!AG5 -> 1103 | L5: =I5-J5-K5 -> 19052857 | M5: =proc_Cambium22_highElec_gea!AI5-proc_Cambium22_MidCase_gea!AI5 -> 1173924 | N5: =proc_Cambium22_highElec_gea!AJ5-proc_Cambium22_MidCase_gea!AJ5 -> -253387.8 | O5: =proc_Cambium22_highElec_gea!AK5-proc_Cambium22_MidCase_gea!AK5 -> 1010.6 | P5: =proc_Cambium22_highElec_gea!AL5-proc_Cambium22_MidCase_gea!AL5 -> 43598 | Q5: =proc_Cambium22_highElec_gea!AM5-proc_Cambium22_MidCase_gea!AM5 -> 18087717 | R5: =M5/L5 -> 0.061614067 | S5: =N5/L5 -> -0.013299202 | T5: =O5/L5 -> 5.3041914e-05 | U5: =P5/L5 -> 0.0022882657 | V5: =Q5/L5 -> 0.9493441
A6: Cambium_2022 | B6: MidCase | C6: AZNMc | D6: 2035 | E6: 0.89 | F6: 81.9 | G6: 149.4 | H6: 398.4 | I6: =proc_Cambium22_highElec_gea!AE6-proc_Cambium22_MidCase_gea!AE6 -> 30910110 | J6: =proc_Cambium22_highElec_gea!AF6-proc_Cambium22_MidCase_gea!AF6 -> 0 | K6: =proc_Cambium22_highElec_gea!AG6-proc_Cambium22_MidCase_gea!AG6 -> 2956.3 | L6: =I6-J6-K6 -> 30907154 | M6: =proc_Cambium22_highElec_gea!AI6-proc_Cambium22_MidCase_gea!AI6 -> 188640.5 | N6: =proc_Cambium22_highElec_gea!AJ6-proc_Cambium22_MidCase_gea!AJ6 -> 1162934.1 | O6: =proc_Cambium22_highElec_gea!AK6-proc_Cambium22_MidCase_gea!AK6 -> 1106.8 | P6: =proc_Cambium22_highElec_gea!AL6-proc_Cambium22_MidCase_gea!AL6 -> 284058 | Q6: =proc_Cambium22_highElec_gea!AM6-proc_Cambium22_MidCase_gea!AM6 -> 29270427 | R6: =M6/L6 -> 0.0061034575 | S6: =N6/L6 -> 0.037626697 | T6: =O6/L6 -> 3.581048e-05 | U6: =P6/L6 -> 0.0091906878 | V6: =Q6/L6 -> 0.94704375
A7: Cambium_2022 | B7: MidCase | C7: AZNMc | D7: 2040 | E7: 0.94 | F7: 50.9 | G7: 190.5 | H7: 357.2 | I7: =proc_Cambium22_highElec_gea!AE7-proc_Cambium22_MidCase_gea!AE7 -> 33150210 | J7: =proc_Cambium22_highElec_gea!AF7-proc_Cambium22_MidCase_gea!AF7 -> 0 | K7: =proc_Cambium22_highElec_gea!AG7-proc_Cambium22_MidCase_gea!AG7 -> 1644.8 | L7: =I7-J7-K7 -> 33148565 | M7: =proc_Cambium22_highElec_gea!AI7-proc_Cambium22_MidCase_gea!AI7 -> 761925.5 | N7: =proc_Cambium22_highElec_gea!AJ7-proc_Cambium22_MidCase_gea!AJ7 -> 3964405.7 | O7: =proc_Cambium22_highElec_gea!AK7-proc_Cambium22_MidCase_gea!AK7 -> -321.4 | P7: =proc_Cambium22_highElec_gea!AL7-proc_Cambium22_MidCase_gea!AL7 -> -5290 | Q7: =proc_Cambium22_highElec_gea!AM7-proc_Cambium22_MidCase_gea!AM7 -> 28427854 | R7: =M7/L7 -> 0.022985173 | S7: =N7/L7 -> 0.11959509 | T7: =O7/L7 -> -9.6957439e-06 | U7: =P7/L7 -> -0.00015958458 | V7: =Q7/L7 -> 0.85758929
A8: Cambium_2022 | B8: MidCase | C8: AZNMc | D8: 2045 | E8: 0.95 | F8: 38 | G8: 189.5 | H8: 261.5 | I8: =proc_Cambium22_highElec_gea!AE8-proc_Cambium22_MidCase_gea!AE8 -> 33088430 | J8: =proc_Cambium22_highElec_gea!AF8-proc_Cambium22_MidCase_gea!AF8 -> 0 | K8: =proc_Cambium22_highElec_gea!AG8-proc_Cambium22_MidCase_gea!AG8 -> 2641.4 | L8: =I8-J8-K8 -> 33085789 | M8: =proc_Cambium22_highElec_gea!AI8-proc_Cambium22_MidCase_gea!AI8 -> 1008711 | N8: =proc_Cambium22_highElec_gea!AJ8-proc_Cambium22_MidCase_gea!AJ8 -> 4609378.9 | O8: =proc_Cambium22_highElec_gea!AK8-proc_Cambium22_MidCase_gea!AK8 -> -71.4 | P8: =proc_Cambium22_highElec_gea!AL8-proc_Cambium22_MidCase_gea!AL8 -> 273272 | Q8: =proc_Cambium22_highElec_gea!AM8-proc_Cambium22_MidCase_gea!AM8 -> 27194503 | R8: =M8/L8 -> 0.030487742 | S8: =N8/L8 -> 0.13931598 | T8: =O8/L8 -> -2.1580262e-06 | U8: =P8/L8 -> 0.0082594979 | V8: =Q8/L8 -> 0.82193908
A9: Cambium_2022 | B9: MidCase | C9: AZNMc | D9: 2050 | E9: 0.94 | F9: 43 | G9: 191.9 | H9: 247.7 | I9: =proc_Cambium22_highElec_gea!AE9-proc_Cambium22_MidCase_gea!AE9 -> 59888600 | J9: =proc_Cambium22_highElec_gea!AF9-proc_Cambium22_MidCase_gea!AF9 -> 0 | K9: =proc_Cambium22_highElec_gea!AG9-proc_Cambium22_MidCase_gea!AG9 -> -410.6 | L9: =I9-J9-K9 -> 59889011 | M9: =proc_Cambium22_highElec_gea!AI9-proc_Cambium22_MidCase_gea!AI9 -> 277159.5 | N9: =proc_Cambium22_highElec_gea!AJ9-proc_Cambium22_MidCase_gea!AJ9 -> 2456072.1 | O9: =proc_Cambium22_highElec_gea!AK9-proc_Cambium22_MidCase_gea!AK9 -> -107.1 | P9: =proc_Cambium22_highElec_gea!AL9-proc_Cambium22_MidCase_gea!AL9 -> -48318 | Q9: =proc_Cambium22_highElec_gea!AM9-proc_Cambium22_MidCase_gea!AM9 -> 57204206 | R9: =M9/L9 -> 0.0046278858 | S9: =N9/L9 -> 0.041010397 | T9: =O9/L9 -> -1.7883081e-06 | U9: =P9/L9 -> -0.00080679242 | V9: =Q9/L9 -> 0.95517033
A10: Cambium_2022 | B10: MidCase | C10: CAMXc | D10: 2024 | E10: 0.71 | F10: 144.9 | G10: 207.5 | H10: 754.3 | I10: =proc_Cambium22_highElec_gea!AE10-proc_Cambium22_MidCase_gea!AE10 -> 763680 | J10: =proc_Cambium22_highElec_gea!AF10-proc_Cambium22_MidCase_gea!AF10 -> 0 | K10: =proc_Cambium22_highElec_gea!AG10-proc_Cambium22_MidCase_gea!AG10 -> -25645 | L10: =I10-J10-K10 -> 789325 | M10: =proc_Cambium22_highElec_gea!AI10-proc_Cambium22_MidCase_gea!AI10 -> 0 | N10: =proc_Cambium22_highElec_gea!AJ10-proc_Cambium22_MidCase_gea!AJ10 -> 510325.5 | O10: =proc_Cambium22_highElec_gea!AK10-proc_Cambium22_MidCase_gea!AK10 -> 1008.7 | P10: =proc_Cambium22_highElec_gea!AL10-proc_Cambium22_MidCase_gea!AL10 -> -81004 | Q10: =proc_Cambium22_highElec_gea!AM10-proc_Cambium22_MidCase_gea!AM10 -> 358998.6 | R10: =M10/L10 -> 0 | S10: =N10/L10 -> 0.64653406 | T10: =O10/L10 -> 0.0012779273 | U10: =P10/L10 -> -0.10262439 | V10: =Q10/L10 -> 0.45481722
A11: Cambium_2022 | B11: MidCase | C11: CAMXc | D11: 2026 | E11: 0.74 | F11: 129.2 | G11: 118.9 | H11: 694.9 | I11: =proc_Cambium22_highElec_gea!AE11-proc_Cambium22_MidCase_gea!AE11 -> 2512160 | J11: =proc_Cambium22_highElec_gea!AF11-proc_Cambium22_MidCase_gea!AF11 -> 0 | K11: =proc_Cambium22_highElec_gea!AG11-proc_Cambium22_MidCase_gea!AG11 -> -3845.5 | L11: =I11-J11-K11 -> 2516005.5 | M11: =proc_Cambium22_highElec_gea!AI11-proc_Cambium22_MidCase_gea!AI11 -> 0 | N11: =proc_Cambium22_highElec_gea!AJ11-proc_Cambium22_MidCase_gea!AJ11 -> -1014194.1 | O11: =proc_Cambium22_highElec_gea!AK11-proc_Cambium22_MidCase_gea!AK11 -> -565.9 | P11: =proc_Cambium22_highElec_gea!AL11-proc_Cambium22_MidCase_gea!AL11 -> -16802 | Q11: =proc_Cambium22_highElec_gea!AM11-proc_Cambium22_MidCase_gea!AM11 -> 3547554.8 | R11: =M11/L11 -> 0 | S11: =N11/L11 -> -0.40309693 | T11: =O11/L11 -> -0.00022492002 | U11: =P11/L11 -> -0.0066780458 | V11: =Q11/L11 -> 1.4099949
A12: Cambium_2022 | B12: MidCase | C12: CAMXc | D12: 2028 | E12: 0.82 | F12: 88.6 | G12: 62.8 | H12: 590.4 | I12: =proc_Cambium22_highElec_gea!AE12-proc_Cambium22_MidCase_gea!AE12 -> 15511140 | J12: =proc_Cambium22_highElec_gea!AF12-proc_Cambium22_MidCase_gea!AF12 -> 0 | K12: =proc_Cambium22_highElec_gea!AG12-proc_Cambium22_MidCase_gea!AG12 -> 28234 | L12: =I12-J12-K12 -> 15482906 | M12: =proc_Cambium22_highElec_gea!AI12-proc_Cambium22_MidCase_gea!AI12 -> 0 | N12: =proc_Cambium22_highElec_gea!AJ12-proc_Cambium22_MidCase_gea!AJ12 -> 1952604.4 | O12: =proc_Cambium22_highElec_gea!AK12-proc_Cambium22_MidCase_gea!AK12 -> 1140.9 | P12: =proc_Cambium22_highElec_gea!AL12-proc_Cambium22_MidCase_gea!AL12 -> 108068 | Q12: =proc_Cambium22_highElec_gea!AM12-proc_Cambium22_MidCase_gea!AM12 -> 13421120 | R12: =M12/L12 -> 0 | S12: =N12/L12 -> 0.12611356 | T12: =O12/L12 -> 7.3687717e-05 | U12: =P12/L12 -> 0.0069798267 | V12: =Q12/L12 -> 0.86683468
A13: Cambium_2022 | B13: MidCase | C13: CAMXc | D13: 2030 | E13: 0.89 | F13: 55.9 | G13: 39.9 | H13: 494.5 | I13: =proc_Cambium22_highElec_gea!AE13-proc_Cambium22_MidCase_gea!AE13 -> 10619040 | J13: =proc_Cambium22_highElec_gea!AF13-proc_Cambium22_MidCase_gea!AF13 -> 0 | K13: =proc_Cambium22_highElec_gea!AG13-proc_Cambium22_MidCase_gea!AG13 -> 25934.5 | L13: =I13-J13-K13 -> 10593106 | M13: =proc_Cambium22_highElec_gea!AI13-proc_Cambium22_MidCase_gea!AI13 -> 0 | N13: =proc_Cambium22_highElec_gea!AJ13-proc_Cambium22_MidCase_gea!AJ13 -> -151739.4 | O13: =proc_Cambium22_highElec_gea!AK13-proc_Cambium22_MidCase_gea!AK13 -> 4774 | P13: =proc_Cambium22_highElec_gea!AL13-proc_Cambium22_MidCase_gea!AL13 -> 0 | Q13: =proc_Cambium22_highElec_gea!AM13-proc_Cambium22_MidCase_gea!AM13 -> 10740059 | R13: =M13/L13 -> 0 | S13: =N13/L13 -> -0.014324355 | T13: =O13/L13 -> 0.00045067049 | U13: =P13/L13 -> 0 | V13: =Q13/L13 -> 1.0138726
A14: Cambium_2022 | B14: MidCase | C14: CAMXc | D14: 2035 | E14: 0.93 | F14: 33.5 | G14: 42.5 | H14: 409.2 | I14: =proc_Cambium22_highElec_gea!AE14-proc_Cambium22_MidCase_gea!AE14 -> 18496160 | J14: =proc_Cambium22_highElec_gea!AF14-proc_Cambium22_MidCase_gea!AF14 -> 0 | K14: =proc_Cambium22_highElec_gea!AG14-proc_Cambium22_MidCase_gea!AG14 -> 63534.4 | L14: =I14-J14-K14 -> 18432626 | M14: =proc_Cambium22_highElec_gea!AI14-proc_Cambium22_MidCase_gea!AI14 -> 0 | N14: =proc_Cambium22_highElec_gea!AJ14-proc_Cambium22_MidCase_gea!AJ14 -> 1549542.4 | O14: =proc_Cambium22_highElec_gea!AK14-proc_Cambium22_MidCase_gea!AK14 -> 6210.6 | P14: =proc_Cambium22_highElec_gea!AL14-proc_Cambium22_MidCase_gea!AL14 -> 0 | Q14: =proc_Cambium22_highElec_gea!AM14-proc_Cambium22_MidCase_gea!AM14 -> 16876899 | R14: =M14/L14 -> 0 | S14: =N14/L14 -> 0.084065202 | T14: =O14/L14 -> 0.00033693518 | U14: =P14/L14 -> 0 | V14: =Q14/L14 -> 0.91559928
... A161: Cambium_2022 | B161: MidCase | C161: SRVCc | D161: 2050 | E161: 0.93 | F161: 38.9 | G161: 113.2 | H161: 511.2 | I161: =proc_Cambium22_highElec_gea!AE161-proc_Cambium22_MidCase_gea!AE161 -> 126092100 | J161: =proc_Cambium22_highElec_gea!AF161-proc_Cambium22_MidCase_gea!AF161 -> 0 | K161: =proc_Cambium22_highElec_gea!AG161-proc_Cambium22_MidCase_gea!AG161 -> 37700.9 | L161: =I161-J161-K161 -> 1.260544e+08 | M161: =proc_Cambium22_highElec_gea!AI161-proc_Cambium22_MidCase_gea!AI161 -> 2080159.8 | N161: =proc_Cambium22_highElec_gea!AJ161-proc_Cambium22_MidCase_gea!AJ161 -> 3735635.8 | O161: =proc_Cambium22_highElec_gea!AK161-proc_Cambium22_MidCase_gea!AK161 -> -17.9 | P161: =proc_Cambium22_highElec_gea!AL161-proc_Cambium22_MidCase_gea!AL161 -> 3194304 | Q161: =proc_Cambium22_highElec_gea!AM161-proc_Cambium22_MidCase_gea!AM161 -> 117044336 | R161: =M161/L161 -> 0.01650208 | S161: =N161/L161 -> 0.029635109 | T161: =O161/L161 -> -1.4200218e-07 | U161: =P161/L161 -> 0.025340678 | V161: =Q161/L161 -> 0.92852242

Sheet proc_Cambium22_MidCase_gea
A1: data_source | B1: scenario | C1: gea_region | D1: year | E1: cef_gen | F1: aer_co2e_kg_per_MWh | G1: lrmer_co2e_kg_per_MWh | H1: srmer_co2e_kg_per_MWh | I1: generation | J1: variable_generation | K1: battery_MWh | L1: biomass_MWh | M1: beccs_MWh | N1: canada_MWh | O1: coal_MWh | P1: coal-ccs_MWh | Q1: csp_MWh | R1: distpv_MWh | S1: gas-cc_MWh | T1: gas-cc-ccs_MWh | U1: gas-ct_MWh | V1: geothermal_MWh | W1: hydro_MWh | X1: nuclear_MWh | Y1: o-g-s_MWh | Z1: phs_MWh | AA1: re-ct_MWh | AB1: upv_MWh | AC1: wind-ons_MWh | AD1: wind-ofs_MWh | AE1: total_generation | AF1: canada_generation | AG1: biomass | AH1: total_generation_adjusted | AI1: total_coal | AJ1: total_natural_gas | AK1: total_oil | AL1: total_nuclear | AM1: total_renewable | AN1: fraction_coal | AO1: fraction_natural_gas | AP1: fraction_oil | AQ1: fraction_nuclear | AR1: fraction_renewable
A2: Cambium_2022 | B2: MidCase | C2: AZNMc | D2: 2024 | E2: 0.63 | F2: 279.4 | G2: 326.9 | H2: 777.1 | I2: 185725700 | J2: 74605900 | K2: 1058299.9 | L2: 268082.6 | M2: 0 | N2: 0 | O2: 22849070 | P2: 0 | Q2: 610865.5 | R2: 4276916 | S2: 45641604 | T2: 0 | U2: 547197.1 | V2: 64042.6 | W2: 9500686 | X2: 30865014 | Y2: 35759 | Z2: 290045.5 | AA2: 0 | AB2: 60049544 | AC2: 9668579 | AD2: 0 | AE2: =I2 -> 185725700 | AF2: =N2 -> 0 | AG2: =SUM(L2,M2) -> 268082.6 | AH2: =AE2-AF2-AG2 -> 1.8545762e+08 | AI2: =SUM(O2,P2) -> 22849070 | AJ2: =SUM(S2,T2,U2) -> 46188801 | AK2: =Y2 -> 35759 | AL2: =X2 -> 30865014 | AM2: =SUM(K2,Q2,R2,V2,W2,Z2,AA2,AB2,AC2,AD2) -> 85518978 | AN2: =AI2/AH2 -> 0.12320373 | AO2: =AJ2/AH2 -> 0.24905314 | AP2: =AK2/AH2 -> 0.00019281494 | AQ2: =AL2/AH2 -> 0.16642624 | AR2: =AM2/AH2 -> 0.46112411
A3: Cambium_2022 | B3: MidCase | C3: AZNMc | D3: 2026 | E3: 0.69 | F3: 237.5 | G3: 193.9 | H3: 709.7 | I3: 192790580 | J3: 87517200 | K3: 3477472.5 | L3: 264561 | M3: 0 | N3: 0 | O3: 21009922 | P3: 0 | Q3: 608656.2 | R3: 5319292.5 | S3: 38507870 | T3: 0 | U3: 421014.4 | V3: 63990.2 | W3: 10746645 | X3: 30392044 | Y3: 26155.8 | Z3: 363703.8 | AA3: 0 | AB3: 70623930 | AC3: 10965319 | AD3: 0 | AE3: =I3 -> 192790580 | AF3: =N3 -> 0 | AG3: =SUM(L3,M3) -> 264561 | AH3: =AE3-AF3-AG3 -> 192526019 | AI3: =SUM(O3,P3) -> 21009922 | AJ3: =SUM(S3,T3,U3) -> 38928884 | AK3: =Y3 -> 26155.8 | AL3: =X3 -> 30392044 | AM3: =SUM(K3,Q3,R3,V3,W3,Z3,AA3,AB3,AC3,AD3) -> 1.0216901e+08 | AN3: =AI3/AH3 -> 0.1091277 | AO3: =AJ3/AH3 -> 0.20220064 | AP3: =AK3/AH3 -> 0.00013585592 | AQ3: =AL3/AH3 -> 0.15785941 | AR3: =AM3/AH3 -> 0.53067637
A4: Cambium_2022 | B4: MidCase | C4: AZNMc | D4: 2028 | E4: 0.8 | F4: 157.9 | G4: 130.5 | H4: 576.4 | I4: 193906060 | J4: 108173544 | K4: 5395934.5 | L4: 255561.7 | M4: 0 | N4: 0 | O4: 14483350 | P4: 0 | Q4: 556958.6 | R4: 6520668.5 | S4: 24957266 | T4: 0 | U4: 199220.8 | V4: 62781.2 | W4: 10590049 | X4: 29352388 | Y4: 19751.4 | Z4: 416224.2 | AA4: 0 | AB4: 81877870 | AC4: 19218034 | AD4: 0 | AE4: =I4 -> 193906060 | AF4: =N4 -> 0 | AG4: =SUM(L4,M4) -> 255561.7 | AH4: =AE4-AF4-AG4 -> 1.936505e+08 | AI4: =SUM(O4,P4) -> 14483350 | AJ4: =SUM(S4,T4,U4) -> 25156487 | AK4: =Y4 -> 19751.4 | AL4: =X4 -> 29352388 | AM4: =SUM(K4,Q4,R4,V4,W4,Z4,AA4,AB4,AC4,AD4) -> 124638520 | AN4: =AI4/AH4 -> 0.074791184 | AO4: =AJ4/AH4 -> 0.12990665 | AP4: =AK4/AH4 -> 0.00010199509 | AQ4: =AL4/AH4 -> 0.15157404 | AR4: =AM4/AH4 -> 0.64362613
A5: Cambium_2022 | B5: MidCase | C5: AZNMc | D5: 2030 | E5: 0.84 | F5: 133.3 | G5: 103.7 | H5: 486.7 | I5: 193562020 | J5: 113367950 | K5: 8528383 | L5: 248627.6 | M5: 0 | N5: 0 | O5: 13433882 | P5: 0 | Q5: 441317.3 | R5: 7608230.5 | S5: 18266398 | T5: 0 | U5: 137996.4 | V5: 61267.8 | W5: 10472780 | X5: 28571094 | Y5: 2684.8 | Z5: 470947.8 | AA5: 0 | AB5: 82395040 | AC5: 22923364 | AD5: 0 | AE5: =I5 -> 193562020 | AF5: =N5 -> 0 | AG5: =SUM(L5,M5) -> 248627.6 | AH5: =AE5-AF5-AG5 -> 1.9331339e+08 | AI5: =SUM(O5,P5) -> 13433882 | AJ5: =SUM(S5,T5,U5) -> 18404394 | AK5: =Y5 -> 2684.8 | AL5: =X5 -> 28571094 | AM5: =SUM(K5,Q5,R5,V5,W5,Z5,AA5,AB5,AC5,AD5) -> 1.3290133e+08 | AN5: =AI5/AH5 -> 0.069492764 | AO5: =AJ5/AH5 -> 0.095204963 | AP5: =AK5/AH5 -> 1.3888329e-05 | AQ5: =AL5/AH5 -> 0.14779676 | AR5: =AM5/AH5 -> 0.68749158
A6: Cambium_2022 | B6: MidCase | C6: AZNMc | D6: 2035 | E6: 0.89 | F6: 81.9 | G6: 149.4 | H6: 398.4 | I6: 210627860 | J6: 128952530 | K6: 20532598 | L6: 225081.4 | M6: 0 | N6: 0 | O6: 8231337.5 | P6: 0 | Q6: 378828.1 | R6: 8916487 | S6: 14103992 | T6: 0 | U6: 113331.4 | V6: 60463.1 | W6: 10419592 | X6: 27536908 | Y6: 4222.1 | Z6: 447807 | AA6: 0 | AB6: 96125930 | AC6: 23531278 | AD6: 0 | AE6: =I6 -> 210627860 | AF6: =N6 -> 0 | AG6: =SUM(L6,M6) -> 225081.4 | AH6: =AE6-AF6-AG6 -> 2.1040278e+08 | AI6: =SUM(O6,P6) -> 8231337.5 | AJ6: =SUM(S6,T6,U6) -> 14217323 | AK6: =Y6 -> 4222.1 | AL6: =X6 -> 27536908 | AM6: =SUM(K6,Q6,R6,V6,W6,Z6,AA6,AB6,AC6,AD6) -> 1.6041298e+08 | AN6: =AI6/AH6 -> 0.03912181 | AO6: =AJ6/AH6 -> 0.067571937 | AP6: =AK6/AH6 -> 2.006675e-05 | AQ6: =AL6/AH6 -> 0.13087711 | AR6: =AM6/AH6 -> 0.76240905
A7: Cambium_2022 | B7: MidCase | C7: AZNMc | D7: 2040 | E7: 0.94 | F7: 50.9 | G7: 190.5 | H7: 357.2 | I7: 241941730 | J7: 154730400 | K7: 33760680 | L7: 218856.6 | M7: 0 | N7: 0 | O7: 6037824 | P7: 0 | Q7: 368334.2 | R7: 8922198 | S7: 9530107 | T7: 0 | U7: 63337.8 | V7: 60463.5 | W7: 10166571 | X7: 26945542 | Y7: 535.6 | Z7: 427417.8 | AA7: 0 | AB7: 114344270 | AC7: 31095594 | AD7: 0 | AE7: =I7 -> 241941730 | AF7: =N7 -> 0 | AG7: =SUM(L7,M7) -> 218856.6 | AH7: =AE7-AF7-AG7 -> 2.4172287e+08 | AI7: =SUM(O7,P7) -> 6037824 | AJ7: =SUM(S7,T7,U7) -> 9593444.8 | AK7: =Y7 -> 535.6 | AL7: =X7 -> 26945542 | AM7: =SUM(K7,Q7,R7,V7,W7,Z7,AA7,AB7,AC7,AD7) -> 1.9914553e+08 | AN7: =AI7/AH7 -> 0.02497829 | AO7: =AJ7/AH7 -> 0.039687782 | AP7: =AK7/AH7 -> 2.2157605e-06 | AQ7: =AL7/AH7 -> 0.11147287 | AR7: =AM7/AH7 -> 0.82385885
A8: Cambium_2022 | B8: MidCase | C8: AZNMc | D8: 2045 | E8: 0.95 | F8: 38 | G8: 189.5 | H8: 261.5 | I8: 264769330 | J8: 171053340 | K8: 44897732 | L8: 211938 | M8: 0 | N8: 0 | O8: 5122842.5 | P8: 0 | Q8: 0 | R8: 8252094.5 | S8: 7293065.5 | T8: 0 | U8: 38752.4 | V8: 48722 | W8: 9580631 | X8: 26072742 | Y8: 107.1 | Z8: 449454 | AA8: 0 | AB8: 132639150 | AC8: 30162106 | AD8: 0 | AE8: =I8 -> 264769330 | AF8: =N8 -> 0 | AG8: =SUM(L8,M8) -> 211938 | AH8: =AE8-AF8-AG8 -> 264557392 | AI8: =SUM(O8,P8) -> 5122842.5 | AJ8: =SUM(S8,T8,U8) -> 7331817.9 | AK8: =Y8 -> 107.1 | AL8: =X8 -> 26072742 | AM8: =SUM(K8,Q8,R8,V8,W8,Z8,AA8,AB8,AC8,AD8) -> 2.2602989e+08 | AN8: =AI8/AH8 -> 0.019363823 | AO8: =AJ8/AH8 -> 0.027713525 | AP8: =AK8/AH8 -> 4.0482709e-07 | AQ8: =AL8/AH8 -> 0.09855231 | AR8: =AM8/AH8 -> 0.85436996
A9: Cambium_2022 | B9: MidCase | C9: AZNMc | D9: 2050 | E9: 0.94 | F9: 43 | G9: 191.9 | H9: 247.7 | I9: 271038600 | J9: 175808600 | K9: 43643510 | L9: 193587.6 | M9: 0 | N9: 0 | O9: 5555184 | P9: 0 | Q9: 0 | R9: 8400748 | S9: 9447664 | T9: 0 | U9: 60913.5 | V9: 0 | W9: 9805172 | X9: 26040922 | Y9: 142.8 | Z9: 482890.2 | AA9: 0 | AB9: 137592000 | AC9: 29815860 | AD9: 0 | AE9: =I9 -> 271038600 | AF9: =N9 -> 0 | AG9: =SUM(L9,M9) -> 193587.6 | AH9: =AE9-AF9-AG9 -> 2.7084501e+08 | AI9: =SUM(O9,P9) -> 5555184 | AJ9: =SUM(S9,T9,U9) -> 9508577.5 | AK9: =Y9 -> 142.8 | AL9: =X9 -> 26040922 | AM9: =SUM(K9,Q9,R9,V9,W9,Z9,AA9,AB9,AC9,AD9) -> 2.2974018e+08 | AN9: =AI9/AH9 -> 0.020510564 | AO9: =AJ9/AH9 -> 0.03510708 | AP9: =AK9/AH9 -> 5.272388e-07 | AQ9: =AL9/AH9 -> 0.09614695 | AR9: =AM9/AH9 -> 0.84823486
A10: Cambium_2022 | B10: MidCase | C10: CAMXc | D10: 2024 | E10: 0.71 | F10: 144.9 | G10: 207.5 | H10: 754.3 | I10: 246363440 | J10: 91679410 | K10: 4226390.5 | L10: 5366078 | M10: 0 | N10: 0 | O10: 0 | P10: 0 | Q10: 1918365 | R10: 21138596 | S10: 70561864 | T10: 0 | U10: 417473 | V10: 23130482 | W10: 27932236 | X10: 17623994 | Y10: 9997.6 | Z10: 5415509 | AA10: 0 | AB10: 53870304 | AC10: 14752144 | AD10: 0 | AE10: =I10 -> 246363440 | AF10: =N10 -> 0 | AG10: =SUM(L10,M10) -> 5366078 | AH10: =AE10-AF10-AG10 -> 240997362 | AI10: =SUM(O10,P10) -> 0 | AJ10: =SUM(S10,T10,U10) -> 70979337 | AK10: =Y10 -> 9997.6 | AL10: =X10 -> 17623994 | AM10: =SUM(K10,Q10,R10,V10,W10,Z10,AA10,AB10,AC10,AD10) -> 1.5238403e+08 | AN10: =AI10/AH10 -> 0 | AO10: =AJ10/AH10 -> 0.29452329 | AP10: =AK10/AH10 -> 4.1484272e-05 | AQ10: =AL10/AH10 -> 0.073129406 | AR10: =AM10/AH10 -> 0.63230579
A11: Cambium_2022 | B11: MidCase | C11: CAMXc | D11: 2026 | E11: 0.74 | F11: 129.2 | G11: 118.9 | H11: 694.9 | I11: 242446260 | J11: 95106984 | K11: 4705290.5 | L11: 5289804.5 | M11: 0 | N11: 0 | O11: 0 | P11: 0 | Q11: 1916708.4 | R11: 24547802 | S11: 62213364 | T11: 0 | U11: 395947.9 | V11: 23130482 | W11: 28328100 | X11: 17396206 | Y11: 7732.7 | Z11: 5872349 | AA11: 0 | AB11: 53953190 | AC11: 14689280 | AD11: 0 | AE11: =I11 -> 242446260 | AF11: =N11 -> 0 | AG11: =SUM(L11,M11) -> 5289804.5 | AH11: =AE11-AF11-AG11 -> 2.3715646e+08 | AI11: =SUM(O11,P11) -> 0 | AJ11: =SUM(S11,T11,U11) -> 62609312 | AK11: =Y11 -> 7732.7 | AL11: =X11 -> 17396206 | AM11: =SUM(K11,Q11,R11,V11,W11,Z11,AA11,AB11,AC11,AD11) -> 1.571432e+08 | AN11: =AI11/AH11 -> 0 | AO11: =AJ11/AH11 -> 0.26400003 | AP11: =AK11/AH11 -> 3.2605901e-05 | AQ11: =AL11/AH11 -> 0.073353289 | AR11: =AM11/AH11 -> 0.66261406
A12: Cambium_2022 | B12: MidCase | C12: CAMXc | D12: 2028 | E12: 0.82 | F12: 88.6 | G12: 62.8 | H12: 590.4 | I12: 247660240 | J12: 113554160 | K12: 8787496 | L12: 5138186.5 | M12: 0 | N12: 0 | O12: 0 | P12: 0 | Q12: 1926788.4 | R12: 28361828 | S12: 43784080 | T12: 0 | U12: 423427 | V12: 24373016 | W12: 27678868 | X12: 16964816 | Y12: 5966.6 | Z12: 6950205 | AA12: 0 | AB12: 66869516 | AC12: 14606058 | AD12: 1789975.4 | AE12: =I12 -> 247660240 | AF12: =N12 -> 0 | AG12: =SUM(L12,M12) -> 5138186.5 | AH12: =AE12-AF12-AG12 -> 2.4252205e+08 | AI12: =SUM(O12,P12) -> 0 | AJ12: =SUM(S12,T12,U12) -> 44207507 | AK12: =Y12 -> 5966.6 | AL12: =X12 -> 16964816 | AM12: =SUM(K12,Q12,R12,V12,W12,Z12,AA12,AB12,AC12,AD12) -> 1.8134375e+08 | AN12: =AI12/AH12 -> 0 | AO12: =AJ12/AH12 -> 0.18228242 | AP12: =AK12/AH12 -> 2.4602299e-05 | AQ12: =AL12/AH12 -> 0.069951643 | AR12: =AM12/AH12 -> 0.74774128
A13: Cambium_2022 | B13: MidCase | C13: CAMXc | D13: 2030 | E13: 0.89 | F13: 55.9 | G13: 39.9 | H13: 494.5 | I13: 286100320 | J13: 166772110 | K13: 18685536 | L13: 4815912.5 | M13: 0 | N13: 0 | O13: 0 | P13: 0 | Q13: 1859431.8 | R13: 32213684 | S13: 32232058 | T13: 0 | U13: 350385 | V13: 24345480 | W13: 26768320 | X13: 0 | Y13: 4614.1 | Z13: 12125892 | AA13: 0 | AB13: 110645890 | AC13: 14813338 | AD13: 7239773 | AE13: =I13 -> 286100320 | AF13: =N13 -> 0 | AG13: =SUM(L13,M13) -> 4815912.5 | AH13: =AE13-AF13-AG13 -> 2.8128441e+08 | AI13: =SUM(O13,P13) -> 0 | AJ13: =SUM(S13,T13,U13) -> 32582443 | AK13: =Y13 -> 4614.1 | AL13: =X13 -> 0 | AM13: =SUM(K13,Q13,R13,V13,W13,Z13,AA13,AB13,AC13,AD13) -> 2.4869734e+08 | AN13: =AI13/AH13 -> 0 | AO13: =AJ13/AH13 -> 0.11583452 | AP13: =AK13/AH13 -> 1.6403682e-05 | AQ13: =AL13/AH13 -> 0 | AR13: =AM13/AH13 -> 0.88414906
... A161: Cambium_2022 | B161: MidCase | C161: SRVCc | D161: 2050 | E161: 0.93 | F161: 38.9 | G161: 113.2 | H161: 511.2 | I161: 501907700 | J161: 271552540 | K161: 62644696 | L161: 1423344.2 | M161: 0 | N161: 0 | O161: 1924772.2 | P161: 0 | Q161: 0 | R161: 19369630 | S161: 33254108 | T161: 0 | U161: 817027 | V161: 0 | W161: 8483493 | X161: 111073256 | Y161: 17.9 | Z161: 10734457 | AA161: 0 | AB161: 223386620 | AC161: 14410226 | AD161: 14386053 | AE161: =I161 -> 501907700 | AF161: =N161 -> 0 | AG161: =SUM(L161,M161) -> 1423344.2 | AH161: =AE161-AF161-AG161 -> 5.0048436e+08 | AI161: =SUM(O161,P161) -> 1924772.2 | AJ161: =SUM(S161,T161,U161) -> 34071135 | AK161: =Y161 -> 17.9 | AL161: =X161 -> 111073256 | AM161: =SUM(K161,Q161,R161,V161,W161,Z161,AA161,AB161,AC161,AD161) -> 353415175 | AN161: =AI161/AH161 -> 0.0038458189 | AO161: =AJ161/AH161 -> 0.068076324 | AP161: =AK161/AH161 -> 3.5765354e-08 | AQ161: =AL161/AH161 -> 0.22193152 | AR161: =AM161/AH161 -> 0.7061463

Sheet proc_Cambium22_highElec_gea
A1: data_source | B1: scenario | C1: gea_region | D1: year | E1: cef_gen | F1: aer_co2e_kg_per_MWh | G1: lrmer_co2e_kg_per_MWh | H1: srmer_co2e_kg_per_MWh | I1: generation | J1: variable_generation | K1: battery_MWh | L1: biomass_MWh | M1: beccs_MWh | N1: canada_MWh | O1: coal_MWh | P1: coal-ccs_MWh | Q1: csp_MWh | R1: distpv_MWh | S1: gas-cc_MWh | T1: gas-cc-ccs_MWh | U1: gas-ct_MWh | V1: geothermal_MWh | W1: hydro_MWh | X1: nuclear_MWh | Y1: o-g-s_MWh | Z1: phs_MWh | AA1: re-ct_MWh | AB1: upv_MWh | AC1: wind-ons_MWh | AD1: wind-ofs_MWh | AE1: total_generation | AF1: canada_generation | AG1: biomass | AH1: total_generation_adjusted | AI1: total_coal | AJ1: total_natural_gas | AK1: total_oil | AL1: total_nuclear | AM1: total_renewable | AN1: fraction_coal | AO1: fraction_natural_gas | AP1: fraction_oil | AQ1: fraction_nuclear | AR1: fraction_renewable
A2: Cambium_2022 | B2: Electrification | C2: AZNMc | D2: 2024 | E2: 0.63 | F2: 275.1 | G2: 338.3 | H2: 745.2 | I2: 188146900 | J2: 77673600 | K2: 649193.4 | L2: 266879.1 | M2: 0 | N2: 0 | O2: 22773602 | P2: 0 | Q2: 605195.6 | R2: 4272841 | S2: 45562904 | T2: 0 | U2: 547089.1 | V2: 64042.6 | W2: 9499519 | X2: 30720758 | Y2: 39158.2 | Z2: 350143.8 | AA2: 0 | AB2: 63126856 | AC2: 9668711 | AD2: 0 | AE2: =I2 -> 188146900 | AF2: =N2 -> 0 | AG2: =SUM(L2,M2) -> 266879.1 | AH2: =AE2-AF2-AG2 -> 1.8788002e+08 | AI2: =SUM(O2,P2) -> 22773602 | AJ2: =SUM(S2,T2,U2) -> 46109993 | AK2: =Y2 -> 39158.2 | AL2: =X2 -> 30720758 | AM2: =SUM(K2,Q2,R2,V2,W2,Z2,AA2,AB2,AC2,AD2) -> 88236502 | AN2: =AI2/AH2 -> 0.12121354 | AO2: =AJ2/AH2 -> 0.24542255 | AP2: =AK2/AH2 -> 0.00020842131 | AQ2: =AL2/AH2 -> 0.16351264 | AR2: =AM2/AH2 -> 0.46964282
A3: Cambium_2022 | B3: Electrification | C3: AZNMc | D3: 2026 | E3: 0.69 | F3: 238.1 | G3: 222.4 | H3: 698.9 | I3: 195086500 | J3: 89076960 | K3: 3839547.5 | L3: 264312 | M3: 0 | N3: 0 | O3: 21744526 | P3: 0 | Q3: 605706.4 | R3: 5320511 | S3: 38269360 | T3: 0 | U3: 331937.7 | V3: 63993.8 | W3: 10742147 | X3: 30355932 | Y3: 21817.5 | Z3: 375966.1 | AA3: 0 | AB3: 72053930 | AC3: 11096814 | AD3: 0 | AE3: =I3 -> 195086500 | AF3: =N3 -> 0 | AG3: =SUM(L3,M3) -> 264312 | AH3: =AE3-AF3-AG3 -> 194822188 | AI3: =SUM(O3,P3) -> 21744526 | AJ3: =SUM(S3,T3,U3) -> 38601298 | AK3: =Y3 -> 21817.5 | AL3: =X3 -> 30355932 | AM3: =SUM(K3,Q3,R3,V3,W3,Z3,AA3,AB3,AC3,AD3) -> 1.0409862e+08 | AN3: =AI3/AH3 -> 0.11161216 | AO3: =AJ3/AH3 -> 0.19813604 | AP3: =AK3/AH3 -> 0.00011198673 | AQ3: =AL3/AH3 -> 0.15581353 | AR3: =AM3/AH3 -> 0.53432628
A4: Cambium_2022 | B4: Electrification | C4: AZNMc | D4: 2028 | E4: 0.78 | F4: 171.3 | G4: 162.9 | H4: 608.7 | I4: 197990560 | J4: 106901096 | K4: 6972082.5 | L4: 257630.4 | M4: 0 | N4: 0 | O4: 16780902 | P4: 0 | Q4: 562184 | R4: 6561916.5 | S4: 26125086 | T4: 0 | U4: 168710.8 | V4: 237320.9 | W4: 10617267 | X4: 29477556 | Y4: 17482 | Z4: 435425 | AA4: 0 | AB4: 84752080 | AC4: 15024920 | AD4: 0 | AE4: =I4 -> 197990560 | AF4: =N4 -> 0 | AG4: =SUM(L4,M4) -> 257630.4 | AH4: =AE4-AF4-AG4 -> 1.9773293e+08 | AI4: =SUM(O4,P4) -> 16780902 | AJ4: =SUM(S4,T4,U4) -> 26293797 | AK4: =Y4 -> 17482 | AL4: =X4 -> 29477556 | AM4: =SUM(K4,Q4,R4,V4,W4,Z4,AA4,AB4,AC4,AD4) -> 1.251632e+08 | AN4: =AI4/AH4 -> 0.084866502 | AO4: =AJ4/AH4 -> 0.13297632 | AP4: =AK4/AH4 -> 8.8412183e-05 | AQ4: =AL4/AH4 -> 0.14907763 | AR4: =AM4/AH4 -> 0.63299116
A5: Cambium_2022 | B5: Electrification | C5: AZNMc | D5: 2030 | E5: 0.85 | F5: 126.9 | G5: 158.1 | H5: 491.9 | I5: 212615980 | J5: 125863016 | K5: 13955925 | L5: 249730.6 | M5: 0 | N5: 0 | O5: 14607806 | P5: 0 | Q5: 494218.2 | R5: 7718514.5 | S5: 18009774 | T5: 0 | U5: 141232.6 | V5: 233912.5 | W5: 10494751 | X5: 28614692 | Y5: 3695.4 | Z5: 441448.6 | AA5: 0 | AB5: 95749620 | AC5: 21900658 | AD5: 0 | AE5: =I5 -> 212615980 | AF5: =N5 -> 0 | AG5: =SUM(L5,M5) -> 249730.6 | AH5: =AE5-AF5-AG5 -> 2.1236625e+08 | AI5: =SUM(O5,P5) -> 14607806 | AJ5: =SUM(S5,T5,U5) -> 18151007 | AK5: =Y5 -> 3695.4 | AL5: =X5 -> 28614692 | AM5: =SUM(K5,Q5,R5,V5,W5,Z5,AA5,AB5,AC5,AD5) -> 1.5098905e+08 | AN5: =AI5/AH5 -> 0.068785911 | AO5: =AJ5/AH5 -> 0.085470298 | AP5: =AK5/AH5 -> 1.740107e-05 | AQ5: =AL5/AH5 -> 0.13474218 | AR5: =AM5/AH5 -> 0.7109842
A6: Cambium_2022 | B6: Electrification | C6: AZNMc | D6: 2035 | E6: 0.9 | F6: 74.3 | G6: 189.7 | H6: 412 | I6: 241537970 | J6: 148120460 | K6: 28770580 | L6: 228037.7 | M6: 0 | N6: 0 | O6: 8419978 | P6: 0 | Q6: 394114.3 | R6: 9013552 | S6: 15197078 | T6: 0 | U6: 183179.5 | V6: 232814.2 | W6: 10440233 | X6: 27820966 | Y6: 5328.9 | Z6: 2119314.5 | AA6: 0 | AB6: 114456550 | AC6: 24256252 | AD6: 0 | AE6: =I6 -> 241537970 | AF6: =N6 -> 0 | AG6: =SUM(L6,M6) -> 228037.7 | AH6: =AE6-AF6-AG6 -> 2.4130993e+08 | AI6: =SUM(O6,P6) -> 8419978 | AJ6: =SUM(S6,T6,U6) -> 15380258 | AK6: =Y6 -> 5328.9 | AL6: =X6 -> 27820966 | AM6: =SUM(K6,Q6,R6,V6,W6,Z6,AA6,AB6,AC6,AD6) -> 189683410 | AN6: =AI6/AH6 -> 0.034892795 | AO6: =AJ6/AH6 -> 0.063736529 | AP6: =AK6/AH6 -> 2.2083219e-05 | AQ6: =AL6/AH6 -> 0.11529143 | AR6: =AM6/AH6 -> 0.7860572
A7: Cambium_2022 | B7: Electrification | C7: AZNMc | D7: 2040 | E7: 0.93 | F7: 55 | G7: 205.9 | H7: 321.9 | I7: 275091940 | J7: 171884670 | K7: 42974650 | L7: 220501.4 | M7: 0 | N7: 0 | O7: 6799749.5 | P7: 0 | Q7: 263911.2 | R7: 8563288 | S7: 13453581 | T7: 0 | U7: 104269.5 | V7: 233051.9 | W7: 10315720 | X7: 26940252 | Y7: 214.2 | Z7: 2165281.8 | AA7: 0 | AB7: 138524820 | AC7: 24532660 | AD7: 0 | AE7: =I7 -> 275091940 | AF7: =N7 -> 0 | AG7: =SUM(L7,M7) -> 220501.4 | AH7: =AE7-AF7-AG7 -> 2.7487144e+08 | AI7: =SUM(O7,P7) -> 6799749.5 | AJ7: =SUM(S7,T7,U7) -> 13557850 | AK7: =Y7 -> 214.2 | AL7: =X7 -> 26940252 | AM7: =SUM(K7,Q7,R7,V7,W7,Z7,AA7,AB7,AC7,AD7) -> 2.2757338e+08 | AN7: =AI7/AH7 -> 0.024737927 | AO7: =AJ7/AH7 -> 0.049324333 | AP7: =AK7/AH7 -> 7.792734e-07 | AQ7: =AL7/AH7 -> 0.098010372 | AR7: =AM7/AH7 -> 0.82792663
A8: Cambium_2022 | B8: Electrification | C8: AZNMc | D8: 2045 | E8: 0.94 | F8: 45.5 | G8: 189.8 | H8: 269.1 | I8: 297857760 | J8: 189940560 | K8: 51425576 | L8: 214579.4 | M8: 0 | N8: 0 | O8: 6131553.5 | P8: 0 | Q8: 0 | R8: 8048455 | S8: 11885557 | T8: 0 | U8: 55639.8 | V8: 220840.1 | W8: 9523651 | X8: 26346014 | Y8: 35.7 | Z8: 2113764 | AA8: 0 | AB8: 156104260 | AC8: 25787846 | AD8: 0 | AE8: =I8 -> 297857760 | AF8: =N8 -> 0 | AG8: =SUM(L8,M8) -> 214579.4 | AH8: =AE8-AF8-AG8 -> 2.9764318e+08 | AI8: =SUM(O8,P8) -> 6131553.5 | AJ8: =SUM(S8,T8,U8) -> 11941197 | AK8: =Y8 -> 35.7 | AL8: =X8 -> 26346014 | AM8: =SUM(K8,Q8,R8,V8,W8,Z8,AA8,AB8,AC8,AD8) -> 2.5322439e+08 | AN8: =AI8/AH8 -> 0.020600349 | AO8: =AJ8/AH8 -> 0.040119168 | AP8: =AK8/AH8 -> 1.1994227e-07 | AQ8: =AL8/AH8 -> 0.08851543 | AR8: =AM8/AH8 -> 0.85076497
A9: Cambium_2022 | B9: Electrification | C9: AZNMc | D9: 2050 | E9: 0.95 | F9: 40 | G9: 187.5 | H9: 229.4 | I9: 330927200 | J9: 214335340 | K9: 61150132 | L9: 193177 | M9: 0 | N9: 0 | O9: 5832343.5 | P9: 0 | Q9: 0 | R9: 8067721 | S9: 11950450 | T9: 0 | U9: 14199.6 | V9: 167714.9 | W9: 9155510 | X9: 25992604 | Y9: 35.7 | Z9: 2135682.2 | AA9: 0 | AB9: 180499220 | AC9: 25768406 | AD9: 0 | AE9: =I9 -> 330927200 | AF9: =N9 -> 0 | AG9: =SUM(L9,M9) -> 193177 | AH9: =AE9-AF9-AG9 -> 330734023 | AI9: =SUM(O9,P9) -> 5832343.5 | AJ9: =SUM(S9,T9,U9) -> 11964650 | AK9: =Y9 -> 35.7 | AL9: =X9 -> 25992604 | AM9: =SUM(K9,Q9,R9,V9,W9,Z9,AA9,AB9,AC9,AD9) -> 2.8694439e+08 | AN9: =AI9/AH9 -> 0.017634543 | AO9: =AJ9/AH9 -> 0.036176047 | AP9: =AK9/AH9 -> 1.0794172e-07 | AQ9: =AL9/AH9 -> 0.078590657 | AR9: =AM9/AH9 -> 0.86759863
A10: Cambium_2022 | B10: Electrification | C10: CAMXc | D10: 2024 | E10: 0.71 | F10: 145.6 | G10: 200.3 | H10: 725.8 | I10: 247127120 | J10: 92188440 | K10: 4130361.5 | L10: 5340433 | M10: 0 | N10: 0 | O10: 0 | P10: 0 | Q10: 1908843.6 | R10: 21138596 | S10: 71015330 | T10: 0 | U10: 474332.5 | V10: 23143360 | W10: 27758156 | X10: 17542990 | Y10: 11006.3 | Z10: 5522712 | AA10: 0 | AB10: 54388852 | AC10: 14752144 | AD10: 0 | AE10: =I10 -> 247127120 | AF10: =N10 -> 0 | AG10: =SUM(L10,M10) -> 5340433 | AH10: =AE10-AF10-AG10 -> 241786687 | AI10: =SUM(O10,P10) -> 0 | AJ10: =SUM(S10,T10,U10) -> 71489662 | AK10: =Y10 -> 11006.3 | AL10: =X10 -> 17542990 | AM10: =SUM(K10,Q10,R10,V10,W10,Z10,AA10,AB10,AC10,AD10) -> 1.5274303e+08 | AN10: =AI10/AH10 -> 0 | AO10: =AJ10/AH10 -> 0.29567245 | AP10: =AK10/AH10 -> 4.5520703e-05 | AQ10: =AL10/AH10 -> 0.072555649 | AR10: =AM10/AH10 -> 0.63172637
A11: Cambium_2022 | B11: Electrification | C11: CAMXc | D11: 2026 | E11: 0.75 | F11: 125.6 | G11: 123.8 | H11: 681.9 | I11: 244958420 | J11: 97800600 | K11: 5430127.5 | L11: 5285959 | M11: 0 | N11: 0 | O11: 0 | P11: 0 | Q11: 1911202.2 | R11: 24547802 | S11: 61172950 | T11: 0 | U11: 422167.8 | V11: 23143360 | W11: 28278886 | X11: 17379404 | Y11: 7166.8 | Z11: 6037786 | AA11: 0 | AB11: 56695830 | AC11: 14645763 | AD11: 0 | AE11: =I11 -> 244958420 | AF11: =N11 -> 0 | AG11: =SUM(L11,M11) -> 5285959 | AH11: =AE11-AF11-AG11 -> 239672461 | AI11: =SUM(O11,P11) -> 0 | AJ11: =SUM(S11,T11,U11) -> 61595118 | AK11: =Y11 -> 7166.8 | AL11: =X11 -> 17379404 | AM11: =SUM(K11,Q11,R11,V11,W11,Z11,AA11,AB11,AC11,AD11) -> 1.6069076e+08 | AN11: =AI11/AH11 -> 0 | AO11: =AJ11/AH11 -> 0.25699706 | AP11: =AK11/AH11 -> 2.9902476e-05 | AQ11: =AL11/AH11 -> 0.072513145 | AR11: =AM11/AH11 -> 0.67045983
A12: Cambium_2022 | B12: Electrification | C12: CAMXc | D12: 2028 | E12: 0.82 | F12: 87.1 | G12: 70.7 | H12: 607.9 | I12: 263171380 | J12: 113988430 | K12: 9943989 | L12: 5166420.5 | M12: 0 | N12: 0 | O12: 0 | P12: 0 | Q12: 1913210.8 | R12: 28361828 | S12: 45700970 | T12: 0 | U12: 459141.4 | V12: 35759140 | W12: 28190918 | X12: 17072884 | Y12: 7107.5 | Z12: 6882393.5 | AA12: 0 | AB12: 67360640 | AC12: 14562776 | AD12: 1789975.4 | AE12: =I12 -> 263171380 | AF12: =N12 -> 0 | AG12: =SUM(L12,M12) -> 5166420.5 | AH12: =AE12-AF12-AG12 -> 2.5800496e+08 | AI12: =SUM(O12,P12) -> 0 | AJ12: =SUM(S12,T12,U12) -> 46160111 | AK12: =Y12 -> 7107.5 | AL12: =X12 -> 17072884 | AM12: =SUM(K12,Q12,R12,V12,W12,Z12,AA12,AB12,AC12,AD12) -> 1.9476487e+08 | AN12: =AI12/AH12 -> 0 | AO12: =AJ12/AH12 -> 0.17891172 | AP12: =AK12/AH12 -> 2.754792e-05 | AQ12: =AL12/AH12 -> 0.066172697 | AR12: =AM12/AH12 -> 0.75488809
A13: Cambium_2022 | B13: Electrification | C13: CAMXc | D13: 2030 | E13: 0.89 | F13: 53.6 | G13: 54.7 | H13: 497 | I13: 296719360 | J13: 164583280 | K13: 15069920 | L13: 4841847 | M13: 0 | N13: 0 | O13: 0 | P13: 0 | Q13: 1903963.2 | R13: 32261280 | S13: 32017540 | T13: 0 | U13: 413163.6 | V13: 35751576 | W13: 26950644 | X13: 0 | Y13: 9388.1 | Z13: 17081986 | AA13: 0 | AB13: 108355580 | AC13: 14822717 | AD13: 7239737.5 | AE13: =I13 -> 296719360 | AF13: =N13 -> 0 | AG13: =SUM(L13,M13) -> 4841847 | AH13: =AE13-AF13-AG13 -> 291877513 | AI13: =SUM(O13,P13) -> 0 | AJ13: =SUM(S13,T13,U13) -> 32430704 | AK13: =Y13 -> 9388.1 | AL13: =X13 -> 0 | AM13: =SUM(K13,Q13,R13,V13,W13,Z13,AA13,AB13,AC13,AD13) -> 2.594374e+08 | AN13: =AI13/AH13 -> 0 | AO13: =AJ13/AH13 -> 0.11111066 | AP13: =AK13/AH13 -> 3.216452e-05 | AQ13: =AL13/AH13 -> 0 | AR13: =AM13/AH13 -> 0.88885711
... A161: Cambium_2022 | B161: Electrification | C161: SRVCc | D161: 2050 | E161: 0.93 | F161: 38.4 | G161: 99.6 | H161: 544.8 | I161: 627999800 | J161: 355038200 | K161: 96710210 | L161: 1461045.1 | M161: 0 | N161: 0 | O161: 4004932 | P161: 0 | Q161: 0 | R161: 19145082 | S161: 35787996 | T161: 0 | U161: 2018774.8 | V161: 0 | W161: 8513682 | X161: 114267560 | Y161: 0 | Z161: 10197425 | AA161: 0 | AB161: 307399680 | AC161: 14373931 | AD161: 14119501 | AE161: =I161 -> 627999800 | AF161: =N161 -> 0 | AG161: =SUM(L161,M161) -> 1461045.1 | AH161: =AE161-AF161-AG161 -> 6.2653875e+08 | AI161: =SUM(O161,P161) -> 4004932 | AJ161: =SUM(S161,T161,U161) -> 37806771 | AK161: =Y161 -> 0 | AL161: =X161 -> 114267560 | AM161: =SUM(K161,Q161,R161,V161,W161,Z161,AA161,AB161,AC161,AD161) -> 470459511 | AN161: =AI161/AH161 -> 0.0063921537 | AO161: =AJ161/AH161 -> 0.06034227 | AP161: =AK161/AH161 -> 0 | AQ161: =AL161/AH161 -> 0.18237908 | AR161: =AM161/AH161 -> 0.75088653

Sheet Cambium22_MidCase_annual_gea
A1: Project | B1: Scenario | C1: Dollar_year | D1: Weather_year | E1: Start_day | F1: country
A2: Cambium_2022 | B2: MidCase | C2: 2021$ | D2: 2012 | E2: Sunday | F2: usa
A3: Metric definitions and scenario descriptions: 2022 Cambium Documentation (https://www.nrel.gov/docs/fy23osti/84916.pdf)
A4: Geography | B4: Time | C4: Load | D4: Load | E4: Load | F4: Load | G4: Load | H4: Load | I4: Load | J4: Transmission | K4: Transmission | L4: Operational | M4: Operational | N4: Operational | O4: Operational | P4: Operational | Q4: Clean Energy Fraction | R4: Clean Energy Fraction | S4: Emissions | T4: Emissions | U4: Emissions | V4: Emissions | W4: Emissions | X4: Emissions | Y4: Emissions | Z4: Emissions | AA4: Emissions | AB4: Emissions | AC4: Emissions | AD4: Emissions | AE4: Emissions | AF4: Emissions | AG4: Emissions | AH4: Emissions | AI4: Emissions | AJ4: Emissions | AK4: Emissions | AL4: Emissions | AM4: Emissions | AN4: Emissions | AO4: Emissions | AP4: Emissions | AQ4: Emissions | AR4: Emissions | AS4: Emissions | AT4: Emissions | AU4: Emissions | AV4: Emissions | AW4: Emissions | AX4: Emissions | AY4: Emissions | AZ4: Emissions | BA4: Emissions | BB4: Emissions | BC4: Emissions | BD4: Emissions | BE4: Emissions | BF4: Emissions | BG4: Emissions | BH4: Emissions | BI4: Emissions | BJ4: Emissions | BK4: Emissions | BL4: Emissions | BM4: Busbar costs | BN4: Busbar costs | BO4: Busbar costs | BP4: Busbar costs | BQ4: End use cost | BR4: End use cost | BS4: End use cost | BT4: End use cost | BU4: Generation | BV4: Generation | BW4: Generation | BX4: Generation | BY4: Generation | BZ4: Generation | CA4: Generation | CB4: Generation | CC4: Generation | CD4: Generation | CE4: Generation | CF4: Generation | CG4: Generation | CH4: Generation | CI4: Generation | CJ4: Generation | CK4: Generation | CL4: Generation | CM4: Generation | CN4: Generation | CO4: Generation | CP4: Generation | CQ4: Capacity | CR4: Capacity | CS4: Capacity | CT4: Capacity | CU4: Capacity | CV4: Capacity | CW4: Capacity | CX4: Capacity | CY4: Capacity | CZ4: Capacity | DA4: Capacity | DB4: Capacity | DC4: Capacity | DD4: Capacity | DE4: Capacity | DF4: Capacity | DG4: Capacity | DH4: Capacity | DI4: Capacity | DJ4: Energy Capacity | DK4: Energy Capacity | DL4: Energy Capacity | DM4: Policy
A5: unitless | B5: unitless | C5: MWh | D5: MWh | E5: MWh | F5: MWh | G5: MWh | H5: MWh | I5: MWh | J5: MWh | K5: MWh | L5: MWh/MWh | M5: MWh/MWh | N5: MW/MW | O5: $/MW | P5: MW | Q5: fraction | R5: fraction | S5: kg/MWh | T5: g/MWh | U5: g/MWh | V5: kg/MWh | W5: g/MWh | X5: g/MWh | Y5: kg/MWh | Z5: kg/MWh | AA5: kg/MWh | AB5: kg/MWh | AC5: g/MWh | AD5: g/MWh | AE5: kg/MWh | AF5: g/MWh | AG5: g/MWh | AH5: kg/MWh | AI5: kg/MWh | AJ5: kg/MWh | AK5: kg/MWh | AL5: g/MWh | AM5: g/MWh | AN5: kg/MWh | AO5: g/MWh | AP5: g/MWh | AQ5: kg/MWh | AR5: kg/MWh | AS5: kg/MWh | AT5: kg/MWh | AU5: g/MWh | AV5: g/MWh | AW5: kg/MWh | AX5: g/MWh | AY5: g/MWh | AZ5: kg/MWh | BA5: kg/MWh | BB5: kg/MWh | BC5: metric tons | BD5: metric tons | BE5: metric tons | BF5: metric tons | BG5: metric tons | BH5: metric tons | BI5: metric tons | BJ5: metric tons | BK5: metric tons | BL5: metric tons | BM5: $/MWh | BN5: $/MWh | BO5: $/MWh | BP5: $/MWh | BQ5: $/MWh | BR5: $/MWh | BS5: $/MWh | BT5: $/MWh | BU5: MWh | BV5: MWh | BW5: MWh | BX5: MWh | BY5: MWh | BZ5: MWh | CA5: MWh | CB5: MWh | CC5: MWh | CD5: MWh | CE5: MWh | CF5: MWh | CG5: MWh | CH5: MWh | CI5: MWh | CJ5: MWh | CK5: MWh | CL5: MWh | CM5: MWh | CN5: MWh | CO5: MWh | CP5: MWh | CQ5: MW | CR5: MW | CS5: MW | CT5: MW | CU5: MW | CV5: MW | CW5: MW | CX5: MW | CY5: MW | CZ5: MW | DA5: MW | DB5: MW | DC5: MW | DD5: MW | DE5: MW | DF5: MW | DG5: MW | DH5: MW | DI5: MW | DJ5: MWh | DK5: MWh | DL5: MWh | DM5: $/ton
A6: gea | B6: t | C6: busbar_load_for_enduse | D6: battery_charging | E6: phs_charging | F6: trans_losses | G6: busbar_load | H6: enduse_load | I6: net_load_busbar | J6: imports | K6: exports | L6: distloss_rate_avg | M6: distloss_rate_marg | N6: prm | O6: capacity_shadow_price | P6: planning_capacity_MW | Q6: cef_gen | R6: cef_load | S6: aer_gen_co2_c | T6: aer_gen_ch4_c | U6: aer_gen_n2o_c | V6: aer_gen_co2_p | W6: aer_gen_ch4_p | X6: aer_gen_n2o_p | Y6: aer_gen_co2e_c | Z6: aer_gen_co2e_p | AA6: aer_gen_co2e | AB6: aer_load_co2_c | AC6: aer_load_ch4_c | AD6: aer_load_n2o_c | AE6: aer_load_co2_p | AF6: aer_load_ch4_p | AG6: aer_load_n2o_p | AH6: aer_load_co2e_c | AI6: aer_load_co2e_p | AJ6: aer_load_co2e | AK6: lrmer_co2_c | AL6: lrmer_ch4_c | AM6: lrmer_n2o_c | AN6: lrmer_co2_p | AO6: lrmer_ch4_p | AP6: lrmer_n2o_p | AQ6: lrmer_co2e_c | AR6: lrmer_co2e_p | AS6: lrmer_co2e | AT6: srmer_co2_c | AU6: srmer_ch4_c | AV6: srmer_n2o_c | AW6: srmer_co2_p | AX6: srmer_ch4_p | AY6: srmer_n2o_p | AZ6: srmer_co2e_c | BA6: srmer_co2e_p | BB6: srmer_co2e | BC6: total_gen_co2_c | BD6: total_gen_ch4_c | BE6: total_gen_n2o_c | BF6: total_gen_co2_p | BG6: total_gen_ch4_p | BH6: total_gen_n2o_p | BI6: total_gen_co2e_c | BJ6: total_gen_co2e_p | BK6: total_gen_co2e | BL6: co2_captured_ccs | BM6: energy_cost_busbar | BN6: capacity_cost_busbar | BO6: portfolio_cost_busbar | BP6: total_cost_busbar | BQ6: energy_cost_enduse | BR6: capacity_cost_enduse | BS6: portfolio_cost_enduse | BT6: total_cost_enduse | BU6: generation | BV6: variable_generation | BW6: battery_MWh | BX6: biomass_MWh | BY6: beccs_MWh | BZ6: canada_MWh | CA6: coal_MWh | CB6: coal-ccs_MWh | CC6: csp_MWh | CD6: distpv_MWh | CE6: gas-cc_MWh | CF6: gas-cc-ccs_MWh | CG6: gas-ct_MWh | CH6: geothermal_MWh | CI6: hydro_MWh | CJ6: nuclear_MWh | CK6: o-g-s_MWh | CL6: phs_MWh | CM6: re-ct_MWh | CN6: upv_MWh | CO6: wind-ons_MWh | CP6: wind-ofs_MWh | CQ6: battery_MW | CR6: biomass_MW | CS6: beccs_MW | CT6: coal_MW | CU6: coal-ccs_MW | CV6: csp_MW | CW6: distpv_MW | CX6: gas-cc_MW | CY6: gas-cc-ccs_MW | CZ6: gas-ct_MW | DA6: geothermal_MW | DB6: hydro_MW | DC6: nuclear_MW | DD6: o-g-s_MW | DE6: phs_MW | DF6: re-ct_MW | DG6: upv_MW | DH6: wind-ofs_MW | DI6: wind-ons_MW | DJ6: battery_energy_cap_MWh | DK6: phs_energy_cap_MWh | DL6: csp_energy_cap_MWh | DM6: co2_shadow_price
A7: AZNMc | B7: 2024 | C7: 143948670 | D7: 1253863 | E7: 365621.2 | F7: 2816673 | G7: 1.4838482e+08 | H7: 1.3877547e+08 | I7: 73778921 | J7: 79080440 | K7: 116053670 | L7: 0.0359 | M7: 0.0539 | N7: 0.1209 | O7: 49905.55 | P7: 34302.5 | Q7: 0.63 | R7: 0.62 | S7: 236 | T7: 17.5 | U7: 2.45 | V7: 17.6 | W7: 825.6 | X7: 0.15 | Y7: 237.2 | Z7: 42.3 | AA7: 279.4 | AB7: 249.6 | AC7: 18.7 | AD7: 2.63 | AE7: 18.3 | AF7: 865.8 | AG7: 0.15 | AH7: 250.9 | AI7: 44.1 | AJ7: 295 | AK7: 257.7 | AL7: 5.8 | AM7: 0.63 | AN7: 29.6 | AO7: 1315.4 | AP7: 0.11 | AQ7: 258 | AR7: 68.9 | AS7: 326.9 | AT7: 661 | AU7: 49.4 | AV7: 6.98 | AW7: 45.4 | AX7: 2254.6 | AY7: 0.34 | AZ7: 664.4 | BA7: 112.6 | BB7: 777.1 | BC7: 43497332 | BD7: 3216.7 | BE7: 452 | BF7: 3247198.6 | BG7: 152168.4 | BH7: 26.8 | BI7: 43716598 | BJ7: 7789125.8 | BK7: 51505723 | BL7: 0 | BM7: 27.96 | BN7: 10.09 | BO7: 0 | BP7: 38.05 | BQ7: 29.71 | BR7: 11.13 | BS7: 0 | BT7: 40.84 | BU7: 185725700 | BV7: 74605900 | BW7: 1058299.9 | BX7: 268082.6 | BY7: 0 | BZ7: 0 | CA7: 22849070 | CB7: 0 | CC7: 610865.5 | CD7: 4276916 | CE7: 45641604 | CF7: 0 | CG7: 547197.1 | CH7: 64042.6 | CI7: 9500686 | CJ7: 30865014 | CK7: 35759 | CL7: 290045.5 | CM7: 0 | CN7: 60049544 | CO7: 9668579 | CP7: 0 | CQ7: 916 | CR7: 42.7 | CS7: 0 | CT7: 4483 | CU7: 0 | CV7: 295.6 | CW7: 2421 | CX7: 16489.7 | CY7: 0 | CZ7: 5487.7 | DA7: 8.6 | DB7: 3963 | DC7: 3937 | DD7: 1118 | DE7: 216.3 | DF7: 0 | DG7: 21937.3 | DH7: 0 | DI7: 2861.3 | DJ7: 2968.3 | DK7: 2163 | DL7: 0 | DM7: 0
A8: AZNMc | B8: 2026 | C8: 147637300 | D8: 4089530.5 | E8: 457150.2 | F8: 3614469.9 | G8: 1.5579844e+08 | H8: 1.4233153e+08 | I8: 68281243 | J8: 106739290 | K8: 143392320 | L8: 0.0359 | M8: 0.0539 | N8: 0.1208 | O8: 66439.3 | P8: 35166 | Q8: 0.69 | R8: 0.69 | S8: 201.1 | T8: 15.3 | U8: 2.16 | V8: 14.8 | W8: 690.2 | X8: 0.13 | Y8: 202.1 | Z8: 35.4 | AA8: 237.5 | AB8: 207 | AC8: 15.7 | AD8: 2.21 | AE8: 15.1 | AF8: 712.5 | AG8: 0.13 | AH8: 208.1 | AI8: 36.4 | AJ8: 244.4 | AK8: 154.1 | AL8: 4.4 | AM8: 0.52 | AN8: 16.9 | AO8: 757.6 | AP8: 0.07 | AQ8: 154.4 | AR8: 39.5 | AS8: 193.9 | AT8: 600.7 | AU8: 43 | AV8: 6.04 | AW8: 42.9 | AX8: 2116.1 | AY8: 0.31 | AZ8: 603.6 | BA8: 106.1 | BB8: 709.7 | BC8: 38459556 | BD8: 2926.9 | BE8: 412.4 | BF8: 2824180.6 | BG8: 132008.8 | BH8: 24.3 | BI8: 38659375 | BJ8: 6764687.9 | BK8: 45424063 | BL8: 0 | BM8: 25.94 | BN8: 13.22 | BO8: 0 | BP8: 39.15 | BQ8: 27.81 | BR8: 14.83 | BS8: 0 | BT8: 42.64 | BU8: 192790580 | BV8: 87517200 | BW8: 3477472.5 | BX8: 264561 | BY8: 0 | BZ8: 0 | CA8: 21009922 | CB8: 0 | CC8: 608656.2 | CD8: 5319292.5 | CE8: 38507870 | CF8: 0 | CG8: 421014.4 | CH8: 63990.2 | CI8: 10746645 | CJ8: 30392044 | CK8: 26155.8 | CL8: 363703.8 | CM8: 0 | CN8: 70623930 | CO8: 10965319 | CP8: 0 | CQ8: 2573.8 | CR8: 42.7 | CS8: 0 | CT8: 4483 | CU8: 0 | CV8: 295.6 | CW8: 3000.3 | CX8: 16489.7 | CY8: 0 | CZ8: 5392.7 | DA8: 8.6 | DB8: 4357 | DC8: 3937 | DD8: 1118 | DE8: 216.3 | DF8: 0 | DG8: 25529.1 | DH8: 0 | DI8: 3194.5 | DJ8: 9599.3 | DK8: 2163 | DL8: 0 | DM8: 0
A9: AZNMc | B9: 2028 | C9: 152042960 | D9: 6293663 | E9: 522529.2 | F9: 4362136.6 | G9: 1.6322129e+08 | H9: 1.4657887e+08 | I9: 55047755 | J9: 137105490 | K9: 167474430 | L9: 0.0359 | M9: 0.0539 | N9: 0.121 | O9: 60595.9 | P9: 36322.3 | Q9: 0.8 | R9: 0.8 | S9: 133.7 | T9: 10.4 | U9: 1.47 | V9: 10 | W9: 452.8 | X9: 0.09 | Y9: 134.4 | Z9: 23.6 | AA9: 157.9 | AB9: 135.9 | AC9: 10.5 | AD9: 1.48 | AE9: 10.1 | AF9: 463.6 | AG9: 0.09 | AH9: 136.7 | AI9: 23.9 | AJ9: 160.6 | AK9: 104.2 | AL9: 3.3 | AM9: 0.41 | AN9: 11.1 | AO9: 501.1 | AP9: 0.05 | AQ9: 104.4 | AR9: 26.1 | AS9: 130.5 | AT9: 484.8 | AU9: 32.7 | AV9: 4.58 | AW9: 36.7 | AX9: 1765.1 | AY9: 0.25 | AZ9: 487 | BA9: 89.4 | BB9: 576.4 | BC9: 25673869 | BD9: 1996.6 | BE9: 281.9 | BF9: 1929129.2 | BG9: 86965.5 | BH9: 18.1 | BI9: 25810338 | BJ9: 4525646.1 | BK9: 30335984 | BL9: 0 | BM9: 20.93 | BN9: 11.87 | BO9: 0 | BP9: 32.8 | BQ9: 22.73 | BR9: 13.5 | BS9: 0 | BT9: 36.23 | BU9: 193906060 | BV9: 108173544 | BW9: 5395934.5 | BX9: 255561.7 | BY9: 0 | BZ9: 0 | CA9: 14483350 | CB9: 0 | CC9: 556958.6 | CD9: 6520668.5 | CE9: 24957266 | CF9: 0 | CG9: 199220.8 | CH9: 62781.2 | CI9: 10590049 | CJ9: 29352388 | CK9: 19751.4 | CL9: 416224.2 | CM9: 0 | CN9: 81877870 | CO9: 19218034 | CP9: 0 | CQ9: 3748.4 | CR9: 42.7 | CS9: 0 | CT9: 4483 | CU9: 0 | CV9: 295.6 | CW9: 3736.8 | CX9: 16039.7 | CY9: 0 | CZ9: 4738.2 | DA9: 8.6 | DB9: 4360 | DC9: 3937 | DD9: 1098 | DE9: 216.3 | DF9: 0 | DG9: 29931.8 | DH9: 0 | DI9: 5373.5 | DJ9: 14656.9 | DK9: 2163 | DL9: 0 | DM9: 0
A10: AZNMc | B10: 2030 | C10: 157141620 | D10: 10031052 | E10: 580361.6 | F10: 4115219 | G10: 1.7186824e+08 | H10: 1.5149429e+08 | I10: 58500288 | J10: 132044780 | K10: 153416140 | L10: 0.0359 | M10: 0.0539 | N10: 0.1209 | O10: 61567.37 | P10: 37735 | Q10: 0.84 | R10: 0.84 | S10: 113.6 | T10: 9.4 | U10: 1.34 | V10: 8.2 | W10: 366.2 | X10: 0.08 | Y10: 114.2 | Z10: 19.1 | AA10: 133.3 | AB10: 110.8 | AC10: 9 | AD10: 1.28 | AE10: 8 | AF10: 362.6 | AG10: 0.08 | AH10: 111.4 | AI10: 18.8 | AJ10: 130.3 | AK10: 83 | AL10: 2.8 | AM10: 0.35 | AN10: 8.7 | AO10: 394.3 | AP10: 0.04 | AQ10: 83.2 | AR10: 20.5 | AS10: 103.7 | AT10: 410.1 | AU10: 28.4 | AV10: 3.99 | AW10: 30.8 | AX10: 1470.2 | AY10: 0.22 | AZ10: 412 | BA10: 74.7 | BB10: 486.7 | BC10: 21747422 | BD10: 1807.7 | BE10: 256.8 | BF10: 1561855.6 | BG10: 70099.4 | BH10: 16.1 | BI10: 21871384 | BJ10: 3655224.2 | BK10: 25526609 | BL10: 0 | BM10: 18.82 | BN10: 11.82 | BO10: 0 | BP10: 30.64 | BQ10: 20.74 | BR10: 13.7 | BS10: 0 | BT10: 34.44 | BU10: 193562020 | BV10: 113367950 | BW10: 8528383 | BX10: 248627.6 | BY10: 0 | BZ10: 0 | CA10: 13433882 | CB10: 0 | CC10: 441317.3 | CD10: 7608230.5 | CE10: 18266398 | CF10: 0 | CG10: 137996.4 | CH10: 61267.8 | CI10: 10472780 | CJ10: 28571094 | CK10: 2684.8 | CL10: 470947.8 | CM10: 0 | CN10: 82395040 | CO10: 22923364 | CP10: 0 | CQ10: 5624.5 | CR10: 42.7 | CS10: 0 | CT10: 4483 | CU10: 0 | CV10: 295.6 | CW10: 4536.1 | CX10: 15671.7 | CY10: 0 | CZ10: 4386.1 | DA10: 8.6 | DB10: 4360 | DC10: 3937 | DD10: 585 | DE10: 216.3 | DF10: 0 | DG10: 32412.6 | DH10: 0 | DI10: 6440.3 | DJ10: 22902.5 | DK10: 2163 | DL10: 0 | DM10: 0
A11: AZNMc | B11: 2035 | C11: 171381460 | D11: 24192988 | E11: 565303.8 | F11: 3780549.1 | G11: 1.9992029e+08 | H11: 1.6522239e+08 | I11: 70967769 | J11: 125248910 | K11: 135705820 | L11: 0.0359 | M11: 0.0539 | N11: 0.1214 | O11: 84675.46 | P11: 41573.8 | Q11: 0.89 | R11: 0.89 | S11: 68.9 | T11: 5.4 | U11: 0.76 | V11: 5.6 | W11: 234.4 | X11: 0.06 | Y11: 69.2 | Z11: 12.6 | AA11: 81.9 | AB11: 70.6 | AC11: 5.4 | AD11: 0.77 | AE11: 5.7 | AF11: 242.4 | AG11: 0.06 | AH11: 71 | AI11: 13 | AJ11: 84 | AK11: 119.1 | AL11: 3.6 | AM11: 0.44 | AN11: 12.9 | AO11: 578.4 | AP11: 0.05 | AQ11: 119.3 | AR11: 30.1 | AS11: 149.4 | AT11: 335 | AU11: 23.2 | AV11: 3.26 | AW11: 25.8 | AX11: 1206.2 | AY11: 0.19 | AZ11: 336.6 | BA11: 61.8 | BB11: 398.4 | BC11: 14336157 | BD11: 1118.1 | BE11: 157.9 | BF11: 1175007.7 | BG11: 48724.7 | BH11: 12.4 | BI11: 14412586 | BJ11: 2630377.8 | BK11: 17042964 | BL11: 0 | BM11: 15.57 | BN11: 15.3 | BO11: 0 | BP11: 30.86 | BQ11: 17.75 | BR11: 18.98 | BS11: 0 | BT11: 36.73 | BU11: 210627860 | BV11: 128952530 | BW11: 20532598 | BX11: 225081.4 | BY11: 0 | BZ11: 0 | CA11: 8231337.5 | CB11: 0 | CC11: 378828.1 | CD11: 8916487 | CE11: 14103992 | CF11: 0 | CG11: 113331.4 | CH11: 60463.1 | CI11: 10419592 | CJ11: 27536908 | CK11: 4222.1 | CL11: 447807 | CM11: 0 | CN11: 96125930 | CO11: 23531278 | CP11: 0 | CQ11: 11059 | CR11: 40.5 | CS11: 0 | CT11: 2181 | CU11: 0 | CV11: 295.6 | CW11: 5682.9 | CX11: 15247.3 | CY11: 0 | CZ11: 4386.1 | DA11: 8.6 | DB11: 4360 | DC11: 3937 | DD11: 359 | DE11: 216.3 | DF11: 0 | DG11: 39402.3 | DH11: 0 | DI11: 6654.3 | DJ11: 56485.7 | DK11: 2163 | DL11: 0 | DM11: 0
A12: AZNMc | B12: 2040 | C12: 188492380 | D12: 39597396 | E12: 541825.8 | F12: 4127271.4 | G12: 2.3275888e+08 | H12: 1.8171837e+08 | I12: 78028485 | J12: 139015660 | K12: 147911470 | L12: 0.0359 | M12: 0.0539 | N12: 0.1218 | O12: 82732.69 | P12: 46020.1 | Q12: 0.94 | R12: 0.93 | S12: 42.7 | T12: 3.4 | U12: 0.48 | V12: 3.7 | W12: 143.3 | X12: 0.04 | Y12: 42.9 | Z12: 8 | AA12: 50.9 | AB12: 44.7 | AC12: 3.6 | AD12: 0.5 | AE12: 3.8 | AF12: 150.1 | AG12: 0.04 | AH12: 44.9 | AI12: 8.3 | AJ12: 53.2 | AK12: 152.7 | AL12: 5.3 | AM12: 0.66 | AN12: 15.9 | AO12: 721.5 | AP12: 0.07 | AQ12: 153 | AR12: 37.5 | AS12: 190.5 | AT12: 300.9 | AU12: 21.2 | AV12: 2.96 | AW12: 22.6 | AX12: 1078.6 | AY12: 0.17 | AZ12: 302.4 | BA12: 54.8 | BB12: 357.2 | BC12: 10169335 | BD12: 814 | BE12: 115.2 | BF12: 881793.4 | BG12: 34074.1 | BH12: 10.3 | BI12: 10225050 | BJ12: 1900008.5 | BK12: 12125058 | BL12: 0 | BM12: 12.63 | BN12: 14.18 | BO12: 0 | BP12: 26.81 | BQ12: 14.73 | BR12: 18.64 | BS12: 0 | BT12: 33.37 | BU12: 241941730 | BV12: 154730400 | BW12: 33760680 | BX12: 218856.6 | BY12: 0 | BZ12: 0 | CA12: 6037824 | CB12: 0 | CC12: 368334.2 | CD12: 8922198 | CE12: 9530107 | CF12: 0 | CG12: 63337.8 | CH12: 60463.5 | CI12: 10166571 | CJ12: 26945542 | CK12: 535.6 | CL12: 427417.8 | CM12: 0 | CN12: 114344270 | CO12: 31095594 | CP12: 0 | CQ12: 17427.2 | CR12: 40.5 | CS12: 0 | CT12: 2065 | CU12: 0 | CV12: 295.6 | CW12: 5908.7 | CX12: 15174.3 | CY12: 0 | CZ12: 4386.1 | DA12: 8.6 | DB12: 4360 | DC12: 3937 | DD12: 175 | DE12: 216.3 | DF12: 0 | DG12: 46970.3 | DH12: 0 | DI12: 8526.8 | DJ12: 94780.9 | DK12: 2163 | DL12: 0 | DM12: 0
A13: AZNMc | B13: 2045 | C13: 205065140 | D13: 52861468 | E13: 574055.2 | F13: 3767009.1 | G13: 262267674 | H13: 1.9769546e+08 | I13: 91214324 | J13: 129935660 | K13: 132147670 | L13: 0.0359 | M13: 0.0539 | N13: 0.1219 | O13: 84348.68 | P13: 50189.1 | Q13: 0.95 | R13: 0.95 | S13: 31.8 | T13: 2.6 | U13: 0.37 | V13: 2.8 | W13: 104.8 | X13: 0.04 | Y13: 32 | Z13: 6 | AA13: 38 | AB13: 33.5 | AC13: 2.8 | AD13: 0.39 | AE13: 3 | AF13: 109.8 | AG13: 0.04 | AH13: 33.7 | AI13: 6.2 | AJ13: 39.9 | AK13: 152.6 | AL13: 5.8 | AM13: 0.74 | AN13: 15.5 | AO13: 705 | AP13: 0.07 | AQ13: 153 | AR13: 36.5 | AS13: 189.5 | AT13: 219 | AU13: 14.9 | AV13: 2.08 | AW13: 17.5 | AX13: 802.3 | AY13: 0.13 | AZ13: 220.1 | BA13: 41.4 | BB13: 261.5 | BC13: 8270260.7 | BD13: 683 | BE13: 96.9 | BF13: 736016.8 | BG13: 27140.9 | BH13: 9.2 | BI13: 8317079.1 | BJ13: 1547332.7 | BK13: 9864411.8 | BL13: 0 | BM13: 9.72 | BN13: 13.93 | BO13: 0 | BP13: 23.66 | BQ13: 11.97 | BR13: 18.96 | BS13: 0 | BT13: 30.93 | BU13: 264769330 | BV13: 171053340 | BW13: 44897732 | BX13: 211938 | BY13: 0 | BZ13: 0 | CA13: 5122842.5 | CB13: 0 | CC13: 0 | CD13: 8252094.5 | CE13: 7293065.5 | CF13: 0 | CG13: 38752.4 | CH13: 48722 | CI13: 9580631 | CJ13: 26072742 | CK13: 107.1 | CL13: 449454 | CM13: 0 | CN13: 132639150 | CO13: 30162106 | CP13: 0 | CQ13: 22312.8 | CR13: 40.5 | CS13: 0 | CT13: 2065 | CU13: 0 | CV13: 0 | CW13: 6218.4 | CX13: 15174.3 | CY13: 0 | CZ13: 4345.6 | DA13: 7 | DB13: 4360 | DC13: 3937 | DD13: 175 | DE13: 216.3 | DF13: 0 | DG13: 56899 | DH13: 0 | DI13: 8367.2 | DJ13: 124723.6 | DK13: 2163 | DL13: 0 | DM13: 0
A14: AZNMc | B14: 2050 | C14: 221323820 | D14: 51305068 | E14: 604198.2 | F14: 3739195.6 | G14: 2.7697228e+08 | H14: 2.1336968e+08 | I14: 1.0116367e+08 | J14: 133208104 | K14: 126987790 | L14: 0.0359 | M14: 0.0539 | N14: 0.1218 | O14: 86747.66 | P14: 53884.6 | Q14: 0.94 | R14: 0.95 | S14: 35.9 | T14: 2.8 | U14: 0.4 | V14: 3.2 | W14: 122.4 | X14: 0.04 | Y14: 36.1 | Z14: 6.8 | AA14: 43 | AB14: 35.6 | AC14: 2.8 | AD14: 0.39 | AE14: 3.2 | AF14: 122.5 | AG14: 0.04 | AH14: 35.8 | AI14: 6.9 | AJ14: 42.7 | AK14: 155.1 | AL14: 6.3 | AM14: 0.81 | AN14: 15.4 | AO14: 704.3 | AP14: 0.07 | AQ14: 155.5 | AR14: 36.4 | AS14: 191.9 | AT14: 203.9 | AU14: 11.3 | AV14: 1.54 | AW14: 18.4 | AX14: 828.7 | AY14: 0.12 | AZ14: 204.6 | BA14: 43.1 | BB14: 247.7 | BC14: 9572509.9 | BD14: 752.5 | BE14: 106.3 | BF14: 847877.8 | BG14: 32524.9 | BH14: 9.8 | BI14: 9623965 | BJ14: 1819795.8 | BK14: 11443761 | BL14: 0 | BM14: 10.37 | BN14: 14.52 | BO14: 0 | BP14: 24.89 | BQ14: 12.72 | BR14: 19.35 | BS14: 0 | BT14: 32.07 | BU14: 271038600 | BV14: 175808600 | BW14: 43643510 | BX14: 193587.6 | BY14: 0 | BZ14: 0 | CA14: 5555184 | CB14: 0 | CC14: 0 | CD14: 8400748 | CE14: 9447664 | CF14: 0 | CG14: 60913.5 | CH14: 0 | CI14: 9805172 | CJ14: 26040922 | CK14: 142.8 | CL14: 482890.2 | CM14: 0 | CN14: 137592000 | CO14: 29815860 | CP14: 0 | CQ14: 22829 | CR14: 38 | CS14: 0 | CT14: 2065 | CU14: 0 | CV14: 0 | CW14: 6703.6 | CX14: 14922.9 | CY14: 0 | CZ14: 4443.6 | DA14: 0 | DB14: 4360 | DC14: 3937 | DD14: 175 | DE14: 216.3 | DF14: 0 | DG14: 61111 | DH14: 0 | DI14: 8243.9 | DJ14: 118475.6 | DK14: 2163 | DL14: 0 | DM14: 0
